Workbook
Name data: Sheet7!#REF!
Name S: Sheet7!$G$103:$I$147
Name S_1: Sheet7!#REF!
Name S_2: Sheet7!#REF!
Name S_3: Sheet7!#REF!
Name S_4: Sheet7!#REF!
Name S_5: Sheet7!$G$8:$I$52
Name S_6: Sheet7!$G$55:$I$99
Name T: Sheet7!$M$103:$O$137
Name T_1: Sheet7!#REF!
Name T_2: Sheet7!#REF!
Name T_3: Sheet7!#REF!
Name T_4: Sheet7!$M$8:$O$42
Name T_5: Sheet7!$M$55:$O$89

Sheet Sheet1
G1: [Na]2 M | H1: 1 | U1: Lin. Fit | V1: Lin. Fit | W1: Nonlin. Fit | X1: Nonlin. Fit | Y1: Nonlin. Fit
B2: e [Abs/mM] | C2: 1.23 | D2: BnOH | F2: fit range [s] | G2: data file | H2: Buf | I2: T [C] | J2: [Buf] M | K2: pH | L2: [Na]0 M | M2: I M | N2: activity of z=-1 | O2: [BnOH] mM | P2: [H2O2] mM | Q2: [Enz] mM | R2: a | S2: b | T2: a/b [Abs/s] | U2: r [Abs/s] | V2: r [mM/s] | W2: r/([H2O2]*a) [1/s] | X2: r/a [mM/s] | Y2: r [mM/s]
B3: e [Abs/mM] | C3: 7.53 | D3: MeOBnOH | F3: SS_smooth | G3: BnOH_uncat_001 | H3: Phos | I3: =25+273.15 -> 298.15 | J3: 0.05 | K3: 7 | L3: 0.07871 | M3: 0.1077 | N3: =10^(-(1.824*10^6)/(78.54*I3)^(3/2))*SQRT(M3) -> 0.10164504 | O3: 0.099 | P3: 122.37 | Q3: 0 | R3: 0.03628 | S3: 17400 | T3: =R3/S3 -> 2.0850575e-06 | U3: 1.077e-06 | V3: =U3/($C$2) -> 8.7560976e-07 | W3: =T3/(P3*$C$2*N3) -> 1.3628617e-07 | X3: =T3/($C$2*N3) -> 1.6677338e-05 | Y3: =T3/($C$2) -> 1.6951687e-06
F4: SS_smooth | G4: BnOH_uncat_001 | H4: Phos | I4: =25+273.15 -> 298.15 | J4: 0.05 | K4: 7 | L4: 0.07871 | M4: 0.1077 | N4: =10^(-(1.824*10^6)/(78.54*I4)^(3/2))*SQRT(M4) -> 0.10164504 | O4: 0.49 | P4: 122.37 | Q4: 0 | R4: 0.1144 | S4: 23790 | T4: =R4/S4 -> 4.8087432e-06 | U4: 3.716e-06 | V4: =U4/($C$2) -> 3.0211382e-06 | W4: =T4/(P4*$C$2*N4) -> 3.1431516e-07 | X4: =T4/($C$2*N4) -> 3.8462746e-05 | Y4: =T4/($C$2) -> 3.9095473e-06
F5: SS_smooth | G5: BnOH_uncat_001 | H5: Phos | I5: =25+273.15 -> 298.15 | J5: 0.05 | K5: 7 | L5: 0.07871 | M5: 0.1077 | N5: =10^(-(1.824*10^6)/(78.54*I5)^(3/2))*SQRT(M5) -> 0.10164504 | O5: 0.99 | P5: 122.37 | Q5: 0 | R5: 0.1642 | S5: 25600 | T5: =R5/S5 -> 6.4140625e-06 | U5: 5.077e-06 | V5: =U5/($C$2) -> 4.1276423e-06 | W5: =T5/(P5*$C$2*N5) -> 4.1924407e-07 | X5: =T5/($C$2*N5) -> 5.1302897e-05 | Y5: =T5/($C$2) -> 5.214685e-06 | AT5: pH = 7.0 | AU5: Km | AV5: kc | AW5: ku | AX5: pH = 8.0 | AY5: Km | AZ5: kc | BA5: ku
F6: SS_smooth | G6: BnOH_uncat_001 | H6: Phos | I6: =25+273.15 -> 298.15 | J6: 0.05 | K6: 7 | L6: 0.07871 | M6: 0.1077 | N6: =10^(-(1.824*10^6)/(78.54*I6)^(3/2))*SQRT(M6) -> 0.10164504 | O6: 2.46 | P6: 122.37 | Q6: 0 | R6: 0.2174 | S6: 24080 | T6: =R6/S6 -> 9.0282392e-06 | U6: 7.075e-06 | V6: =U6/($C$2) -> 5.7520325e-06 | W6: =T6/(P6*$C$2*N6) -> 5.901152e-07 | X6: =T6/($C$2*N6) -> 7.2212397e-05 | Y6: =T6/($C$2) -> 7.3400319e-06 | AT6: fit 1 | AU6: 0.5694 | AV6: 7.484e-06 | AW6: 1.102e-07 | AX6: fit 1 | AY6: 0.7099 | AZ6: 1.679e-05 | BA6: 1.029e-06
F7: SS_smooth | G7: BnOH_uncat_001 | H7: Phos | I7: =25+273.15 -> 298.15 | J7: 0.05 | K7: 7 | L7: 0.07871 | M7: 0.1077 | N7: =10^(-(1.824*10^6)/(78.54*I7)^(3/2))*SQRT(M7) -> 0.10164504 | O7: 9.85 | P7: 122.37 | Q7: 0 | R7: 0.3731 | S7: 33170 | T7: =R7/S7 -> 1.1248116e-05 | U7: 9.309e-06 | V7: =U7/($C$2) -> 7.5682927e-06 | W7: =T7/(P7*$C$2*N7) -> 7.3521358e-07 | X7: =T7/($C$2*N7) -> 8.9968086e-05 | Y7: =T7/($C$2) -> 9.1448096e-06 | AT7: fit 2 | AU7: 0.6985 | AV7: 8.398e-06
F8: SS_smooth | G8: BnOH_uncat_002 | H8: Phos | I8: =25+273.15 -> 298.15 | J8: 0.05 | K8: 7 | L8: 0.07871 | M8: 0.1077 | N8: =10^(-(1.824*10^6)/(78.54*I8)^(3/2))*SQRT(M8) -> 0.10164504 | O8: 0.099 | P8: 122.37 | Q8: 0 | R8: 0.01999 | S8: 9685 | T8: =R8/S8 -> 2.0640165e-06 | U8: 1.742e-06 | V8: =U8/($C$2) -> 1.4162602e-06 | W8: =T8/(P8*$C$2*N8) -> 1.3491086e-07 | X8: =T8/($C$2*N8) -> 1.6509042e-05 | Y8: =T8/($C$2) -> 1.6780622e-06
F9: SS_smooth | G9: BnOH_uncat_002 | H9: Phos | I9: =25+273.15 -> 298.15 | J9: 0.05 | K9: 7 | L9: 0.07871 | M9: 0.1077 | N9: =10^(-(1.824*10^6)/(78.54*I9)^(3/2))*SQRT(M9) -> 0.10164504 | O9: 0.49 | P9: 122.37 | Q9: 0 | R9: 0.1506 | S9: 29400 | T9: =R9/S9 -> 5.122449e-06 | U9: 4.614e-06 | V9: =U9/($C$2) -> 3.7512195e-06 | W9: =T9/(P9*$C$2*N9) -> 3.3481999e-07 | X9: =T9/($C$2*N9) -> 4.0971923e-05 | Y9: =T9/($C$2) -> 4.1645927e-06 | AM9: Benzyl alcohol phosphoric
F10: SS_smooth | G10: BnOH_uncat_002 | H10: Phos | I10: =25+273.15 -> 298.15 | J10: 0.05 | K10: 7 | L10: 0.07871 | M10: 0.1077 | N10: =10^(-(1.824*10^6)/(78.54*I10)^(3/2))*SQRT(M10) -> 0.10164504 | O10: 0.99 | P10: 122.37 | Q10: 0 | R10: 0.2867 | S10: 38610 | T10: =R10/S10 -> 7.4255374e-06 | U10: 6.854e-06 | V10: =U10/($C$2) -> 5.5723577e-06 | W10: =T10/(P10*$C$2*N10) -> 4.8535738e-07 | X10: =T10/($C$2*N10) -> 5.9393182e-05 | Y10: =T10/($C$2) -> 6.0370223e-06 | AM10: sub ph 7 | AN10: =G3 -> BnOH_uncat_001 | AO10: =G8 -> BnOH_uncat_002 | AP10: =G13 -> BnOH_uncat_003 | AQ10: mean [M/s] | AR10: s | AS10: w | AT10: s/2 | AU10: 5*s/2
F11: SS_smooth | G11: BnOH_uncat_002 | H11: Phos | I11: =25+273.15 -> 298.15 | J11: 0.05 | K11: 7 | L11: 0.07871 | M11: 0.1077 | N11: =10^(-(1.824*10^6)/(78.54*I11)^(3/2))*SQRT(M11) -> 0.10164504 | O11: 2.46 | P11: 122.37 | Q11: 0 | R11: 0.3705 | S11: 42630 | T11: =R11/S11 -> 8.6910626e-06 | U11: 7.731e-06 | V11: =U11/($C$2) -> 6.2853659e-06 | W11: =T11/(P11*$C$2*N11) -> 5.6807624e-07 | X11: =T11/($C$2*N11) -> 6.9515489e-05 | Y11: =T11/($C$2) -> 7.0659046e-06 | AM11: =O3 -> 0.099 | AN11: =V3 -> 8.7560976e-07 | AO11: =V8 -> 1.4162602e-06 | AP11: =V13 -> 1.0674797e-06 | AQ11: =(AN11+AO11+AP11)/3 -> 1.1197832e-06 | AR11: =SQRT(0.5*((AN11-AQ11)^2+(AO11-AQ11)^2+(AP11-AQ11)^2)) -> 2.7409389e-07 | AS11: =1/AR11 -> 3648384.9 | AT11: =AR11/2 -> 1.3704694e-07 | AU11: 1.43e-06
F12: SS_smooth | G12: BnOH_uncat_002 | H12: Phos | I12: =25+273.15 -> 298.15 | J12: 0.05 | K12: 7 | L12: 0.07871 | M12: 0.1077 | N12: =10^(-(1.824*10^6)/(78.54*I12)^(3/2))*SQRT(M12) -> 0.10164504 | O12: 9.85 | P12: 122.37 | Q12: 0 | R12: 0.7107 | S12: 65230 | T12: =R12/S12 -> 1.0895294e-05 | U12: 1.02e-05 | V12: =U12/($C$2) -> 8.2926829e-06 | W12: =T12/(P12*$C$2*N12) -> 7.1215197e-07 | X12: =T12/($C$2*N12) -> 8.7146037e-05 | Y12: =T12/($C$2) -> 8.8579623e-06 | AM12: =O4 -> 0.49 | AN12: =V4 -> 3.0211382e-06 | AO12: =V9 -> 3.7512195e-06 | AP12: =V14 -> 3.8317073e-06 | AQ12: =(AN12+AO12+AP12)/3 -> 3.5346883e-06 | AR12: =SQRT(0.5*((AN12-AQ12)^2+(AO12-AQ12)^2+(AP12-AQ12)^2)) -> 4.4656453e-07 | AS12: =1/AR12 -> 2239318 | AT12: =AR12/2 -> 2.2328226e-07 | AU12: 1.43e-06 | AX12: sub | AY12: fit 1 | AZ12: fit 2 | BA12: fit 3
F13: SS_smooth | G13: BnOH_uncat_003 | H13: Phos | I13: =25+273.15 -> 298.15 | J13: 0.05 | K13: 7 | L13: 0.07871 | M13: 0.1077 | N13: =10^(-(1.824*10^6)/(78.54*I13)^(3/2))*SQRT(M13) -> 0.10164504 | O13: 0.099 | P13: 122.37 | Q13: 0 | R13: 0.04518 | S13: 29250 | T13: =R13/S13 -> 1.5446154e-06 | U13: 1.313e-06 | V13: =U13/($C$2) -> 1.0674797e-06 | W13: =T13/(P13*$C$2*N13) -> 1.0096111e-07 | X13: =T13/($C$2*N13) -> 1.2354611e-05 | Y13: =T13/($C$2) -> 1.2557849e-06 | AM13: =O5 -> 0.99 | AN13: =V5 -> 4.1276423e-06 | AO13: =V10 -> 5.5723577e-06 | AP13: =V15 -> 6.0487805e-06 | AQ13: =(AN13+AO13+AP13)/3 -> 5.2495935e-06 | AR13: =SQRT(0.5*((AN13-AQ13)^2+(AO13-AQ13)^2+(AP13-AQ13)^2))/2 -> 5.0020635e-07 | AS13: =1/AR13 -> 1999174.9 | AT13: =AR13/2 -> 2.5010317e-07 | AU13: 1.43e-06 | AX13: 0 | AY13: =($AV$6*AX13)/($AU$6+AX13)+AX13*$AW$6 -> 0 | AZ13: =($AV$7*AX13)/($AU$7+AX13) -> 0 | BA13: =($AZ$6*AX13)/($AY$6+AX13)+AX13*$BA$6 -> 0
F14: SS_smooth | G14: BnOH_uncat_003 | H14: Phos | I14: =25+273.15 -> 298.15 | J14: 0.05 | K14: 7 | L14: 0.07871 | M14: 0.1077 | N14: =10^(-(1.824*10^6)/(78.54*I14)^(3/2))*SQRT(M14) -> 0.10164504 | O14: 0.49 | P14: 122.37 | Q14: 0 | R14: 0.1778 | S14: 34740 | T14: =R14/S14 -> 5.1180196e-06 | U14: 4.713e-06 | V14: =U14/($C$2) -> 3.8317073e-06 | W14: =T14/(P14*$C$2*N14) -> 3.3453047e-07 | X14: =T14/($C$2*N14) -> 4.0936494e-05 | Y14: =T14/($C$2) -> 4.1609915e-06 | AM14: =O6 -> 2.46 | AN14: =V6 -> 5.7520325e-06 | AO14: =V11 -> 6.2853659e-06 | AP14: =V16 -> 6.3073171e-06 | AQ14: =(AN14+AO14+AP14)/3 -> 6.1149051e-06 | AR14: =SQRT(0.5*((AN14-AQ14)^2+(AO14-AQ14)^2+(AP14-AQ14)^2)) -> 3.1444852e-07 | AS14: =1/AR14 -> 3180170.8 | AT14: =AR14/2 -> 1.5722426e-07 | AU14: 1.43e-06 | AX14: 0.1 | AY14: =($AV$6*AX14)/($AU$6+AX14)+AX14*$AW$6 -> 1.1290361e-06 | AZ14: =($AV$7*AX14)/($AU$7+AX14) -> 1.051722e-06 | BA14: =($AZ$6*AX14)/($AY$6+AX14)+AX14*$BA$6 -> 2.1759954e-06
B15: pyrophosphate | C15: 6.7 | F15: SS_smooth | G15: BnOH_uncat_003 | H15: Phos | I15: =25+273.15 -> 298.15 | J15: 0.05 | K15: 7 | L15: 0.07871 | M15: 0.1077 | N15: =10^(-(1.824*10^6)/(78.54*I15)^(3/2))*SQRT(M15) -> 0.10164504 | O15: 0.99 | P15: 122.37 | Q15: 0 | R15: 0.2763 | S15: 34260 | T15: =R15/S15 -> 8.0647986e-06 | U15: 7.44e-06 | V15: =U15/($C$2) -> 6.0487805e-06 | W15: =T15/(P15*$C$2*N15) -> 5.2714157e-07 | X15: =T15/($C$2*N15) -> 6.4506314e-05 | Y15: =T15/($C$2) -> 6.5567468e-06 | AM15: =O7 -> 9.85 | AN15: =V7 -> 7.5682927e-06 | AO15: =V12 -> 8.2926829e-06 | AP15: =V17 -> 8.5691057e-06 | AQ15: =(AN15+AO15+AP15)/3 -> 8.1433604e-06 | AR15: =SQRT(0.5*((AN15-AQ15)^2+(AO15-AQ15)^2+(AP15-AQ15)^2)) -> 5.1684579e-07 | AS15: =1/AR15 -> 1934813.1 | AT15: =AR15/2 -> 2.584229e-07 | AU15: 1.43e-06 | AX15: 0.2 | AY15: =($AV$6*AX15)/($AU$6+AX15)+AX15*$AW$6 -> 1.967452e-06 | AZ15: =($AV$7*AX15)/($AU$7+AX15) -> 1.8693378e-06 | BA15: =($AZ$6*AX15)/($AY$6+AX15)+AX15*$BA$6 -> 3.8963154e-06
B16: Boric acid pKa | C16: 9.24 | F16: SS_smooth | G16: BnOH_uncat_003 | H16: Phos | I16: =25+273.15 -> 298.15 | J16: 0.05 | K16: 7 | L16: 0.07871 | M16: 0.1077 | N16: =10^(-(1.824*10^6)/(78.54*I16)^(3/2))*SQRT(M16) -> 0.10164504 | O16: 2.46 | P16: 122.37 | Q16: 0 | R16: 2.388 | S16: 298700 | T16: =R16/S16 -> 7.9946435e-06 | U16: 7.758e-06 | V16: =U16/($C$2) -> 6.3073171e-06 | W16: =T16/(P16*$C$2*N16) -> 5.22556e-07 | X16: =T16/($C$2*N16) -> 6.3945178e-05 | Y16: =T16/($C$2) -> 6.4997101e-06 | AR16: =2*AR15 -> 1.0336916e-06 | AS16: =1/AR16 -> 967406.54 | AX16: 0.3 | AY16: =($AV$6*AX16)/($AU$6+AX16)+AX16*$AW$6 -> 2.6155307e-06 | AZ16: =($AV$7*AX16)/($AU$7+AX16) -> 2.5231848e-06 | BA16: =($AZ$6*AX16)/($AY$6+AX16)+AX16*$BA$6 -> 5.2963225e-06
B17: NaH2PO4 pKa | C17: 6.865 | F17: SS_smooth | G17: BnOH_uncat_003 | H17: Phos | I17: =25+273.15 -> 298.15 | J17: 0.05 | K17: 7 | L17: 0.07871 | M17: 0.1077 | N17: =10^(-(1.824*10^6)/(78.54*I17)^(3/2))*SQRT(M17) -> 0.10164504 | O17: 9.85 | P17: 122.37 | Q17: 0 | R17: 1.964 | S17: 180400 | T17: =R17/S17 -> 1.0886918e-05 | U17: 1.054e-05 | V17: =U17/($C$2) -> 8.5691057e-06 | W17: =T17/(P17*$C$2*N17) -> 7.1160451e-07 | X17: =T17/($C$2*N17) -> 8.7079044e-05 | Y17: =T17/($C$2) -> 8.8511528e-06 | AX17: 0.4 | AY17: =($AV$6*AX17)/($AU$6+AX17)+AX17*$AW$6 -> 3.1321757e-06 | AZ17: =($AV$7*AX17)/($AU$7+AX17) -> 3.0579882e-06 | BA17: =($AZ$6*AX17)/($AY$6+AX17)+AX17*$BA$6 -> 6.4625956e-06
F18: SS_smooth | G18: data69 | H18: Phos | I18: =25+273.15 -> 298.15 | J18: 0.085 | K18: 8.01 | L18: 0.1641 | M18: 0.2434 | N18: =10^(-(1.824*10^6)/(78.54*I18)^(3/2))*SQRT(M18) -> 0.15280537 | O18: 0.21 | P18: 122.43 | Q18: 0 | R18: 0.311 | S18: 39970 | T18: =R18/S18 -> 7.7808356e-06 | U18: 6.328e-06 | V18: =U18/($C$2) -> 5.1447154e-06 | W18: =T18/(P18*$C$2*N18) -> 3.3813853e-07 | X18: =T18/($C$2*N18) -> 4.13983e-05 | Y18: =T18/($C$2) -> 6.3258826e-06 | AX18: 0.5 | AY18: =($AV$6*AX18)/($AU$6+AX18)+AX18*$AW$6 -> 3.5542584e-06 | AZ18: =($AV$7*AX18)/($AU$7+AX18) -> 3.5035461e-06 | BA18: =($AZ$6*AX18)/($AY$6+AX18)+AX18*$BA$6 -> 7.45309e-06
B19: Vmax (1/s) | C19: Km M | E19: bad curv | F19: SS_smooth | G19: data69 | H19: Phos | I19: =25+273.15 -> 298.15 | J19: 0.085 | K19: 8.01 | L19: 0.1641 | M19: 0.2434 | N19: =10^(-(1.824*10^6)/(78.54*I19)^(3/2))*SQRT(M19) -> 0.15280537 | O19: 0.42 | P19: 122.43 | Q19: 0 | R19: 0.229 | S19: 39970 | T19: =R19/S19 -> 5.729297e-06 | U19: 4.021e-06 | V19: =U19/($C$2) -> 3.2691057e-06 | W19: =T19/(P19*$C$2*N19) -> 2.4898303e-07 | X19: =T19/($C$2*N19) -> 3.0482993e-05 | Y19: =T19/($C$2) -> 4.657965e-06 | AX19: 0.6 | AY19: =($AV$6*AX19)/($AU$6+AX19)+AX19*$AW$6 -> 3.9060379e-06 | AZ19: =($AV$7*AX19)/($AU$7+AX19) -> 3.8804775e-06 | BA19: =($AZ$6*AX19)/($AY$6+AX19)+AX19*$BA$6 -> 8.3080634e-06
B20: 1.335e-06 | C20: 0.1169 | F20: SS_smooth | G20: data69 | H20: Phos | I20: =25+273.15 -> 298.15 | J20: 0.085 | K20: 8.01 | L20: 0.1641 | M20: 0.2434 | N20: =10^(-(1.824*10^6)/(78.54*I20)^(3/2))*SQRT(M20) -> 0.15280537 | O20: 1.05 | P20: 122.43 | Q20: 0 | R20: 0.9121 | S20: 39970 | T20: =R20/S20 -> 2.2819615e-05 | U20: 2.187e-05 | V20: =U20/($C$2) -> 1.7780488e-05 | W20: =T20/(P20*$C$2*N20) -> 9.9169181e-07 | X20: =T20/($C$2*N20) -> 0.00012141283 | Y20: =T20/($C$2) -> 1.8552532e-05 | AM20: Benzyl alcohol phosphoric | AX20: 0.7 | AY20: =($AV$6*AX20)/($AU$6+AX20)+AX20*$AW$6 -> 4.2041291e-06 | AZ20: =($AV$7*AX20)/($AU$7+AX20) -> 4.2035038e-06 | BA20: =($AZ$6*AX20)/($AY$6+AX20)+AX20*$BA$6 -> 9.0563522e-06
F21: SS_smooth | G21: data69 | H21: Phos | I21: =25+273.15 -> 298.15 | J21: 0.085 | K21: 8.01 | L21: 0.1641 | M21: 0.2434 | N21: =10^(-(1.824*10^6)/(78.54*I21)^(3/2))*SQRT(M21) -> 0.15280537 | O21: 2.11 | P21: 122.43 | Q21: 0 | R21: 0.9893 | S21: 39970 | T21: =R21/S21 -> 2.4751063e-05 | U21: 2.479e-05 | V21: =U21/($C$2) -> 2.0154472e-05 | W21: =T21/(P21*$C$2*N21) -> 1.0756284e-06 | X21: =T21/($C$2*N21) -> 0.00013168919 | Y21: =T21/($C$2) -> 2.0122816e-05 | AM21: sub ph 8 | AN21: data69 | AO21: data70 | AP21: data67 | AQ21: mean | AR21: s | AS21: w | AT21: s/2 | AX21: 0.8 | AY21: =($AV$6*AX21)/($AU$6+AX21)+AX21*$AW$6 -> 4.4602938e-06 | AZ21: =($AV$7*AX21)/($AU$7+AX21) -> 4.4834168e-06 | BA21: =($AZ$6*AX21)/($AY$6+AX21)+AX21*$BA$6 -> 9.7191534e-06
F22: 200 smooth | G22: data70 | H22: Phos | I22: =25+273.15 -> 298.15 | J22: 0.085 | K22: 8.01 | L22: 0.1641 | M22: 0.2434 | N22: =10^(-(1.824*10^6)/(78.54*I22)^(3/2))*SQRT(M22) -> 0.15280537 | O22: 0.21 | P22: 122.43 | Q22: 0 | R22: 0.4212 | S22: 40000 | T22: =R22/S22 -> 1.053e-05 | U22: 1.227e-05 | V22: =U22/($C$2) -> 9.9756098e-06 | W22: =T22/(P22*$C$2*N22) -> 4.5761135e-07 | X22: =T22/($C$2*N22) -> 5.6025358e-05 | Y22: =T22/($C$2) -> 8.5609756e-06 | AM22: =O18 -> 0.21 | AN22: =V18 -> 5.1447154e-06 | AO22: =V22 -> 9.9756098e-06 | AQ22: =(AN22+AO22)/2 -> 7.5601626e-06 | AR22: =SQRT(((AN22-AQ22)^2+(AO22-AQ22)^2)) -> 3.4159581e-06 | AS22: =1/AR22 -> 292743.64 | AT22: =AR22/2 -> 1.7079791e-06 | AX22: 0.9 | AY22: =($AV$6*AX22)/($AU$6+AX22)+AX22*$AW$6 -> 4.6830918e-06 | AZ22: =($AV$7*AX22)/($AU$7+AX22) -> 4.7283078e-06 | BA22: =($AZ$6*AX22)/($AY$6+AX22)+AX22*$BA$6 -> 1.0312397e-05
F23: 200 smooth | G23: data70 | H23: Phos | I23: =25+273.15 -> 298.15 | J23: 0.085 | K23: 8.01 | L23: 0.1641 | M23: 0.2434 | N23: =10^(-(1.824*10^6)/(78.54*I23)^(3/2))*SQRT(M23) -> 0.15280537 | O23: 0.42 | P23: 122.43 | Q23: 0 | R23: 0.784 | S23: 39970 | T23: =R23/S23 -> 1.9614711e-05 | U23: 2.378e-05 | V23: =U23/($C$2) -> 1.9333333e-05 | W23: =T23/(P23*$C$2*N23) -> 8.5241353e-07 | X23: =T23/($C$2*N23) -> 0.00010436099 | Y23: =T23/($C$2) -> 1.594692e-05 | AM23: =O19 -> 0.42 | AN23: =V19 -> 3.2691057e-06 | AO23: =V23 -> 1.9333333e-05 | AQ23: =(AN23+AO23)/2 -> 1.130122e-05 | AR23: =SQRT(((AN23-AQ23)^2+(AO23-AQ23)^2)) -> 1.1359124e-05 | AS23: =1/AR23 -> 88034.955 | AT23: =AR23/2 -> 5.6795622e-06 | AX23: 1 | AY23: =($AV$6*AX23)/($AU$6+AX23)+AX23*$AW$6 -> 4.8789014e-06 | AZ23: =($AV$7*AX23)/($AU$7+AX23) -> 4.9443627e-06 | BA23: =($AZ$6*AX23)/($AY$6+AX23)+AX23*$BA$6 -> 1.0848288e-05
F24: 200 smooth | G24: data70 | H24: Phos | I24: =25+273.15 -> 298.15 | J24: 0.085 | K24: 8.01 | L24: 0.1641 | M24: 0.2434 | N24: =10^(-(1.824*10^6)/(78.54*I24)^(3/2))*SQRT(M24) -> 0.15280537 | O24: 1.05 | P24: 122.43 | Q24: 0 | R24: 1.082 | S24: 39970 | T24: =R24/S24 -> 2.7070303e-05 | U24: 2.842e-05 | V24: =U24/($C$2) -> 2.3105691e-05 | W24: =T24/(P24*$C$2*N24) -> 1.1764176e-06 | X24: =T24/($C$2*N24) -> 0.00014402881 | Y24: =T24/($C$2) -> 2.2008376e-05 | AM24: =O20 -> 1.05 | AN24: =V20 -> 1.7780488e-05 | AO24: =V24 -> 2.3105691e-05 | AQ24: =(AN24+AO24)/2 -> 2.0443089e-05 | AR24: =SQRT(((AN24-AQ24)^2+(AO24-AQ24)^2)) -> 3.7654873e-06 | AS24: =1/AR24 -> 265569.88 | AT24: =AR24/2 -> 1.8827437e-06 | AX24: 1.1 | AY24: =($AV$6*AX24)/($AU$6+AX24)+AX24*$AW$6 -> 5.0525726e-06 | AZ24: =($AV$7*AX24)/($AU$7+AX24) -> 5.1363914e-06 | BA24: =($AZ$6*AX24)/($AY$6+AX24)+AX24*$BA$6 -> 1.1336331e-05
F25: 200 smooth | G25: data70 | H25: Phos | I25: =25+273.15 -> 298.15 | J25: 0.085 | K25: 8.01 | L25: 0.1641 | M25: 0.2434 | N25: =10^(-(1.824*10^6)/(78.54*I25)^(3/2))*SQRT(M25) -> 0.15280537 | O25: 2.11 | P25: 122.43 | Q25: 0 | R25: 1.008 | S25: 39970 | T25: =R25/S25 -> 2.5218914e-05 | U25: 2.553e-05 | V25: =U25/($C$2) -> 2.0756098e-05 | W25: =T25/(P25*$C$2*N25) -> 1.0959602e-06 | X25: =T25/($C$2*N25) -> 0.00013417841 | Y25: =T25/($C$2) -> 2.0503182e-05 | AM25: =O21 -> 2.11 | AN25: =V21 -> 2.0154472e-05 | AO25: =V25 -> 2.0756098e-05 | AQ25: =(AN25+AO25)/2 -> 2.0455285e-05 | AR25: =SQRT(((AN25-AQ25)^2+(AO25-AQ25)^2)) -> 4.2541384e-07 | AS25: =1/AR25 -> 2350652.3 | AT25: =AR25/2 -> 2.1270692e-07 | AX25: 1.2 | AY25: =($AV$6*AX25)/($AU$6+AX25)+AX25*$AW$6 -> 5.2078589e-06 | AZ25: =($AV$7*AX25)/($AU$7+AX25) -> 5.3081907e-06 | BA25: =($AZ$6*AX25)/($AY$6+AX25)+AX25*$BA$6 -> 1.1784043e-05
F26: 200 smooth | G26: data67 | H26: Phos | I26: =25+273.15 -> 298.15 | J26: 0.085 | K26: 8.01 | L26: 0.1641 | M26: 0.2434 | N26: =10^(-(1.824*10^6)/(78.54*I26)^(3/2))*SQRT(M26) -> 0.15280537 | O26: 0.37 | P26: 122.43 | Q26: 0 | R26: 0.2967 | S26: 39970 | T26: =R26/S26 -> 7.4230673e-06 | U26: 7.231e-06 | V26: =U26/($C$2) -> 5.8788618e-06 | W26: =T26/(P26*$C$2*N26) -> 3.2259068e-07 | X26: =T26/($C$2*N26) -> 3.9494777e-05 | Y26: =T26/($C$2) -> 6.0350141e-06 | AM26: =O26 -> 0.37 | AP26: =V26 -> 5.8788618e-06 | AQ26: =AP26 -> 5.8788618e-06 | AR26: =AR25 -> 4.2541384e-07 | AS26: =1/AR26 -> 2350652.3 | AT26: =AR26/2 -> 2.1270692e-07 | AX26: 1.3 | AY26: =($AV$6*AX26)/($AU$6+AX26)+AX26*$AW$6 -> 5.3477106e-06 | AZ26: =($AV$7*AX26)/($AU$7+AX26) -> 5.4627971e-06 | BA26: =($AZ$6*AX26)/($AY$6+AX26)+AX26*$BA$6 -> 1.2197444e-05
F27: 200 smooth | G27: data67 | H27: Phos | I27: =25+273.15 -> 298.15 | J27: 0.085 | K27: 8.01 | L27: 0.1641 | M27: 0.2434 | N27: =10^(-(1.824*10^6)/(78.54*I27)^(3/2))*SQRT(M27) -> 0.15280537 | O27: 1.83 | P27: 122.43 | Q27: 0 | R27: 0.6886 | S27: 39970 | T27: =R27/S27 -> 1.7227921e-05 | U27: 1.817e-05 | V27: =U27/($C$2) -> 1.4772358e-05 | W27: =T27/(P27*$C$2*N27) -> 7.4868872e-07 | X27: =T27/($C$2*N27) -> 9.166196e-05 | Y27: =T27/($C$2) -> 1.400644e-05 | AM27: =O28 -> 3.7 | AP27: =V28 -> 1.6878049e-05 | AQ27: =AP27 -> 1.6878049e-05 | AR27: =AR26 -> 4.2541384e-07 | AS27: =1/AR27 -> 2350652.3 | AT27: =AR27/2 -> 2.1270692e-07 | AX27: 1.4 | AY27: =($AV$6*AX27)/($AU$6+AX27)+AX27*$AW$6 -> 5.474479e-06 | AZ27: =($AV$7*AX27)/($AU$7+AX27) -> 5.6026686e-06 | BA27: =($AZ$6*AX27)/($AY$6+AX27)+AX27*$BA$6 -> 1.2581412e-05
F28: 200 smooth | G28: data67 | H28: Phos | I28: =25+273.15 -> 298.15 | J28: 0.085 | K28: 8.01 | L28: 0.1641 | M28: 0.2434 | N28: =10^(-(1.824*10^6)/(78.54*I28)^(3/2))*SQRT(M28) -> 0.15280537 | O28: 3.7 | P28: 122.43 | Q28: 0 | R28: 0.8415 | S28: 39970 | T28: =R28/S28 -> 2.105329e-05 | U28: 2.076e-05 | V28: =U28/($C$2) -> 1.6878049e-05 | W28: =T28/(P28*$C$2*N28) -> 9.149311e-07 | X28: =T28/($C$2*N28) -> 0.00011201501 | Y28: =T28/($C$2) -> 1.7116496e-05 | AM28: =O29 -> 7.31 | AP28: =V29 -> 2.2756098e-05 | AQ28: =AP28 -> 2.2756098e-05 | AR28: =AR27 -> 4.2541384e-07 | AS28: =1/AR28 -> 2350652.3 | AT28: =AR28/2 -> 2.1270692e-07 | AX28: 1.5 | AY28: =($AV$6*AX28)/($AU$6+AX28)+AX28*$AW$6 -> 5.5900608e-06 | AZ28: =($AV$7*AX28)/($AU$7+AX28) -> 5.7298158e-06 | BA28: =($AZ$6*AX28)/($AY$6+AX28)+AX28*$BA$6 -> 1.2939943e-05
F29: 200 smooth | G29: data67 | H29: Phos | I29: =25+273.15 -> 298.15 | J29: 0.085 | K29: 8.01 | L29: 0.1641 | M29: 0.2434 | N29: =10^(-(1.824*10^6)/(78.54*I29)^(3/2))*SQRT(M29) -> 0.15280537 | O29: 7.31 | P29: 122.43 | Q29: 0 | R29: 1.101 | S29: 39970 | T29: =R29/S29 -> 2.7545659e-05 | U29: 2.799e-05 | V29: =U29/($C$2) -> 2.2756098e-05 | W29: =T29/(P29*$C$2*N29) -> 1.1970756e-06 | X29: =T29/($C$2*N29) -> 0.00014655797 | Y29: =T29/($C$2) -> 2.2394845e-05 | AX29: 1.6 | AY29: =($AV$6*AX29)/($AU$6+AX29)+AX29*$AW$6 -> 5.6960029e-06 | AZ29: =($AV$7*AX29)/($AU$7+AX29) -> 5.8458995e-06 | BA29: =($AZ$6*AX29)/($AY$6+AX29)+AX29*$BA$6 -> 1.3276341e-05
F30: 1000 smooth | G30: data65 | H30: Boric | I30: =25+273.15 -> 298.15 | J30: 0.0875 | K30: 8.51 | L30: 0.01347 | M30: 0.01347 | N30: =10^(-(1.824*10^6)/(78.54*I30)^(3/2))*SQRT(M30) -> 0.035946957 | O30: 0.37 | P30: 122.43 | Q30: 0 | R30: 0.8305 | S30: 54620 | T30: =R30/S30 -> 1.5205053e-05 | U30: 1.509e-05 | V30: =U30/($C$2) -> 1.2268293e-05 | W30: =T30/(P30*$C$2*N30) -> 2.8088778e-06 | X30: =T30/($C$2*N30) -> 0.00034389091 | Y30: =T30/($C$2) -> 1.2361832e-05 | AX30: 1.7 | AY30: =($AV$6*AX30)/($AU$6+AX30)+AX30*$AW$6 -> 5.7935795e-06 | AZ30: =($AV$7*AX30)/($AU$7+AX30) -> 5.9523035e-06 | BA30: =($AZ$6*AX30)/($AY$6+AX30)+AX30*$BA$6 -> 1.359336e-05
F31: 1000 smooth | G31: data65 | H31: Boric | I31: =25+273.15 -> 298.15 | J31: 0.0875 | K31: 8.51 | L31: 0.01347 | M31: 0.01347 | N31: =10^(-(1.824*10^6)/(78.54*I31)^(3/2))*SQRT(M31) -> 0.035946957 | O31: 1.83 | P31: 122.43 | Q31: 0 | R31: 1.378 | S31: 54530 | T31: =R31/S31 -> 2.5270493e-05 | U31: 2.507e-05 | V31: =U31/($C$2) -> 2.0382114e-05 | W31: =T31/(P31*$C$2*N31) -> 4.6682986e-06 | X31: =T31/($C$2*N31) -> 0.0005715398 | Y31: =T31/($C$2) -> 2.0545117e-05 | AX31: 1.8 | AY31: =($AV$6*AX31)/($AU$6+AX31)+AX31*$AW$6 -> 5.88385e-06 | AZ31: =($AV$7*AX31)/($AU$7+AX31) -> 6.0501901e-06 | BA31: =($AZ$6*AX31)/($AY$6+AX31)+AX31*$BA$6 -> 1.3893317e-05
F32: 1000 smooth | G32: data65 | H32: Boric | I32: =25+273.15 -> 298.15 | J32: 0.0875 | K32: 8.51 | L32: 0.01347 | M32: 0.01347 | N32: =10^(-(1.824*10^6)/(78.54*I32)^(3/2))*SQRT(M32) -> 0.035946957 | O32: 3.7 | P32: 122.43 | Q32: 0 | R32: 1.897 | S32: 54490 | T32: =R32/S32 -> 3.4813727e-05 | U32: 3.454e-05 | V32: =U32/($C$2) -> 2.8081301e-05 | W32: =T32/(P32*$C$2*N32) -> 6.4312506e-06 | X32: =T32/($C$2*N32) -> 0.00078737801 | Y32: =T32/($C$2) -> 2.8303843e-05 | AX32: 1.9 | AY32: =($AV$6*AX32)/($AU$6+AX32)+AX32*$AW$6 -> 5.9677019e-06 | AZ32: =($AV$7*AX32)/($AU$7+AX32) -> 6.1405426e-06 | BA32: =($AZ$6*AX32)/($AY$6+AX32)+AX32*$BA$6 -> 1.4178174e-05
F33: 1000 smooth | G33: data65 | H33: Boric | I33: =25+273.15 -> 298.15 | J33: 0.0875 | K33: 8.51 | L33: 0.01347 | M33: 0.01347 | N33: =10^(-(1.824*10^6)/(78.54*I33)^(3/2))*SQRT(M33) -> 0.035946957 | O33: 7.31 | P33: 122.43 | Q33: 0 | R33: 1.817 | S33: 50010 | T33: =R33/S33 -> 3.6332733e-05 | U33: 3.601e-05 | V33: =U33/($C$2) -> 2.9276423e-05 | W33: =T33/(P33*$C$2*N33) -> 6.7118614e-06 | X33: =T33/($C$2*N33) -> 0.00082173319 | Y33: =T33/($C$2) -> 2.9538808e-05 | AX33: 2 | AY33: =($AV$6*AX33)/($AU$6+AX33)+AX33*$AW$6 -> 6.0458845e-06 | AZ33: =($AV$7*AX33)/($AU$7+AX33) -> 6.2241986e-06 | BA33: =($AZ$6*AX33)/($AY$6+AX33)+AX33*$BA$6 -> 1.4449601e-05
AX34: 2.1 | AY34: =($AV$6*AX34)/($AU$6+AX34)+AX34*$AW$6 -> 6.1190352e-06 | AZ34: =($AV$7*AX34)/($AU$7+AX34) -> 6.301876e-06 | BA34: =($AZ$6*AX34)/($AY$6+AX34)+AX34*$BA$6 -> 1.4709033e-05
AX35: 2.2 | AY35: =($AV$6*AX35)/($AU$6+AX35)+AX35*$AW$6 -> 6.1876989e-06 | AZ35: =($AV$7*AX35)/($AU$7+AX35) -> 6.3741935e-06 | BA35: =($AZ$6*AX35)/($AY$6+AX35)+AX35*$BA$6 -> 1.4957707e-05
AX36: 2.3 | AY36: =($AV$6*AX36)/($AU$6+AX36)+AX36*$AW$6 -> 6.2523448e-06 | AZ36: =($AV$7*AX36)/($AU$7+AX36) -> 6.4416875e-06 | BA36: =($AZ$6*AX36)/($AY$6+AX36)+AX36*$BA$6 -> 1.5196694e-05
AX37: 2.4 | AY37: =($AV$6*AX37)/($AU$6+AX37)+AX37*$AW$6 -> 6.3133788e-06 | AZ37: =($AV$7*AX37)/($AU$7+AX37) -> 6.5048249e-06 | BA37: =($AZ$6*AX37)/($AY$6+AX37)+AX37*$BA$6 -> 1.542693e-05
M38: =M33 -> 0.01347 | AA38: T | AB38: T | AC38: Vmax (mM/s) | AD38: Km | AE38: Vmax/Km | AF38: 1/T | AG38: ln(Vmax) | AH38: R*ln(kcat*h/T*kB) | AI38: R*ln(kcat*h/Kd*T*kB) | AJ38: ln(Km/T) | AX38: 2.5 | AY38: =($AV$6*AX38)/($AU$6+AX38)+AX38*$AW$6 -> 6.3711539e-06 | AZ38: =($AV$7*AX38)/($AU$7+AX38) -> 6.5640144e-06 | BA38: =($AZ$6*AX38)/($AY$6+AX38)+AX38*$BA$6 -> 1.5649231e-05
J39: 0.05 M | AA39: 298.15 K | AB39: =15+273.15 -> 288.15 | AC39: 4.554e-06 | AD39: 0.1766 | AE39: =AC39/AD39 -> 2.5787089e-05 | AF39: =1/AB39 -> 0.0034704147 | AG39: =LN(AC39) -> -12.299505 | AH39: =(1.98816*LN((AC39/AB39)*0.0000000000479924))/1000 -> -0.082951929 | AI39: =(1.98816*LN((AC39/(AB39*AD39))*0.0000000000479924))/1000 -> -0.079504722 | AJ39: =LN(AD39/AB39) -> -7.3973492 | AX39: 2.6 | AY39: =($AV$6*AX39)/($AU$6+AX39)+AX39*$AW$6 -> 6.4259786e-06 | AZ39: =($AV$7*AX39)/($AU$7+AX39) -> 6.619615e-06 | BA39: =($AZ$6*AX39)/($AY$6+AX39)+AX39*$BA$6 -> 1.5864318e-05
J40: 0.085 | L40: 85 mM | N40: =M3 -> 0.1077 | AA40: 308.15 K | AB40: 308.15 | AC40: 8.017e-06 | AD40: 0.1369 | AE40: =AC40/AD40 -> 5.8560993e-05 | AF40: =1/AB40 -> 0.0032451728 | AG40: =LN(AC40) -> -11.733946 | AH40: =(1.98816*LN((AC40/AB40)*0.0000000000479924))/1000 -> -0.081960925 | AI40: =(1.98816*LN((AC40/(AB40*AD40))*0.0000000000479924))/1000 -> -0.078007459 | AJ40: =LN(AD40/AB40) -> -7.7190912 | AX40: 2.7 | AY40: =($AV$6*AX40)/($AU$6+AX40)+AX40*$AW$6 -> 6.4781236e-06 | AZ40: =($AV$7*AX40)/($AU$7+AX40) -> 6.6719435e-06 | BA40: =($AZ$6*AX40)/($AY$6+AX40)+AX40*$BA$6 -> 1.6072825e-05
...

Sheet Sheet2
A1: B1=631G(d) B2=631+G(d) B3=631+G(d,p) B4=6311+G(2d,p) B5=6311+G(2df,2p)
A2: M05/B2 | B2: M05/B2 | C2: M05/B3 | D2: M05/B3 S^2 | E2: M05/B4 | F2: M05/B4 S^2 | G2: M05/B5 | H2: M05/B5 S^2 | I2: M05/B2 UAKS | J2: M05/B2 BONDI | K2: M05/B1 BONDI | L2: M05/B2 PAULING | M2: M05 v (1/cm) | N2: M05 ZPVE(corr) | O2: M05 H(corr) | P2: M05 G(corr) | Q2: M05 -TS(corr) | R2: M05/B2 Ee+ZPVE (kCal/mol) | S2: M05/B3 Ee+ZPVE (kCal/mol) | T2: M05/B5 Ee+ZPVE (kCal/mol) | U2: M05/B5 H (kCal/mol) | V2: M05/B5 G (kCal/mol) | W2: M05/B5 G+UAKS/B2 (kCal/mol) | X2: M05/B5 G+Bondi/B2 (kCal/mol) | Y2: M05/B5 G+Bondi/B1 (kCal/mol) | Z2: M05/B4 G+Bondi/B1 (kCal/mol) | AA2: M05/B3 G+Bondi/B1 (kCal/mol) | AB2: M05/B5 G+Pauling/B2 (kCal/mol) | AH2: DGb_TS1 | AI2: DGa_TS1 | AJ2: (DGb+Dga)_TS1 | AK2: AD(DGa) | AL2: AD(exp) | AN2: DGb_TS1(-) | AO2: DGa_TS1(-) | AP2: (DGb+Dga)_TS1(-) | AQ2: AD(DGa) | AR2: DGb_TS1(Na) | AS2: DGa_TS1(NA) | AT2: (DGb+Dga)_TS1(Na) | AU2: AD(DGa)
A3: BnOH | B3: -346.53391 | C3: -346.54976 | E3: -346.60331 | G3: -346.61532 | I3: -6.93 | J3: -5.05 | K3: -4.23 | L3: -4.4 | N3: 0.13431 | O3: 0.142321 | P3: 0.102271 | Q3: =O3-P3 -> 0.04005 | R3: =((B3+N3)*$BJ$3*$BJ$4*10^-3)/$BJ$5 -> -217368.96 | S3: =((C3+N3)*$BJ$3*$BJ$4*10^-3)/$BJ$5 -> -217378.91 | T3: =((G3+N3)*$BJ$3*$BJ$4*10^-3)/$BJ$5 -> -217420.05 | U3: =((G3+N3)*$BJ$3*$BJ$4*10^-3)/$BJ$5 -> -217420.05 | V3: =((G3+P3)*$BJ$3*$BJ$4*10^-3)/$BJ$5 -> -217440.15 | W3: =((G3+P3)*$BJ$3*$BJ$4*10^-3)/$BJ$5+I3 -> -217447.08 | X3: =((G3+P3)*$BJ$3*$BJ$4*10^-3)/$BJ$5+J3 -> -217445.2 | AB3: =((G3+P3)*$BJ$3*$BJ$4*10^-3)/$BJ$5+L3 -> -217444.55 | AF3: BS-U/RB3LYP | AG3: B3//B2 | AH3: =S93-(S81+S83)-2.3 -> 1.8916058 | AI3: =S91-(S93)-0.6 -> 31.251637 | AJ3: =AH3+AI3 -> 33.143243 | AL3: =ABS($AJ$29-AJ3) -> 3.4432427 | AZ3: structure | BA3: kCal/mol | BB3: S**2 | BC3: x | BD3: BS-UDFT corrected | BI3: Hartree (J/particle) | BJ3: 4.3597439e-18
A4: ONIOM/B2 BnOH | B4: -115.61156 | C4: -346.54908 | E4: -346.6028 | G4: -346.61467 | I4: -7.02 | J4: -5.38 | K4: -4.54 | L4: -4.48 | N4: 0.132396 | O4: 0.140518 | P4: 0.099673 | Q4: =O4-P4 -> 0.040845 | R4: =((B4+N4)*$BJ$3*$BJ$4*10^-3)/$BJ$5 -> -72464.249 | S4: =((C4+N4)*$BJ$3*$BJ$4*10^-3)/$BJ$5 -> -217379.69 | T4: =((G4+N4)*$BJ$3*$BJ$4*10^-3)/$BJ$5 -> -217420.85 | U4: =((G4+N4)*$BJ$3*$BJ$4*10^-3)/$BJ$5 -> -217420.85 | V4: =((G4+P4)*$BJ$3*$BJ$4*10^-3)/$BJ$5 -> -217441.38 | W4: =((G4+P4)*$BJ$3*$BJ$4*10^-3)/$BJ$5+I4 -> -217448.4 | X4: =((G4+P4)*$BJ$3*$BJ$4*10^-3)/$BJ$5+J4 -> -217446.76 | Y4: =((G4+P4)*$BJ$3*$BJ$4*10^-3)/$BJ$5+K4 -> -217445.92 | Z4: =((E4+P4)*$BJ$3*$BJ$4*10^-3)/$BJ$5+K4 -> -217438.47 | AA4: =((C4+P4)*$BJ$3*$BJ$4*10^-3)/$BJ$5+K4 -> -217404.76 | AB4: =((G4+P4)*$BJ$3*$BJ$4*10^-3)/$BJ$5+L4 -> -217445.86 | AF4: AP-U/RB3LYP | AG4: B3//B2 | AH4: =S93-(S81+S83)-2.3 -> 1.8916058 | AI4: =-312722.33-(S93)-0.6 -> 25.35398 | AJ4: =AH4+AI4 -> 27.245585 | AL4: =ABS($AJ$29-AJ4) -> 2.4544145 | AZ4: BS-UDFT singlet | BA4: =-805.51122605*627.509469 -> -505465.92 | BB4: 0.9242 | BC4: =(BB4-BB6)/(BB5-BB4) -> 0.85908161 | BD4: =BA4+BC4*(BA4-BA5) -> -505446.06 | BI4: Na (1/mol) | BJ4: 6.02214e+23
A5: ONIOM/B1 BnOH | C5: -346.54911 | E5: -346.60286 | G5: -346.61473 | I5: -7 | J5: -5.3 | K5: -4.49 | L5: -4.31 | N5: 0.132564 | O5: 0.140666 | P5: 0.100018 | Q5: =O5-P5 -> 0.040648 | R5: =((B5+N5)*$BJ$3*$BJ$4*10^-3)/$BJ$5 -> 83.18514 | S5: =((C5+N5)*$BJ$3*$BJ$4*10^-3)/$BJ$5 -> -217379.6 | T5: =((G5+N5)*$BJ$3*$BJ$4*10^-3)/$BJ$5 -> -217420.78 | U5: =((G5+N5)*$BJ$3*$BJ$4*10^-3)/$BJ$5 -> -217420.78 | V5: =((G5+P5)*$BJ$3*$BJ$4*10^-3)/$BJ$5 -> -217441.2 | W5: =((G5+P5)*$BJ$3*$BJ$4*10^-3)/$BJ$5+I5 -> -217448.2 | X5: =((G5+P5)*$BJ$3*$BJ$4*10^-3)/$BJ$5+J5 -> -217446.5 | Y5: =((G5+P5)*$BJ$3*$BJ$4*10^-3)/$BJ$5+K5 -> -217445.69 | Z5: =((E5+P5)*$BJ$3*$BJ$4*10^-3)/$BJ$5+K5 -> -217438.24 | AA5: =((C5+P5)*$BJ$3*$BJ$4*10^-3)/$BJ$5+K5 -> -217404.51 | AB5: =((G5+P5)*$BJ$3*$BJ$4*10^-3)/$BJ$5+L5 -> -217445.51 | AF5: BS-U/RB3LYP | AG5: B3//B2 + Bondi/B2 | AH5: =U93-(U81+U83)-2.3 -> 8.9316058 | AI5: =U91-U93-0.6 -> 23.481637 | AJ5: =AH5+AI5 -> 32.413243 | AL5: =ABS($AJ$29-AJ5) -> 2.7132427 | AZ5: UDFT triplet | BA5: =-805.54806828*627.509469 -> -505489.04 | BB5: 2 | BD5: DIF kCal/mol | BI5: joul/cal | BJ5: 4.184
A6: MeOBnOH | B6: -461.00187 | C6: -461.0201 | G6: -461.11334 | I6: -8.37 | J6: -6.77 | L6: -4.42 | N6: 0.167382 | O6: 0.177962 | P6: 0.13172 | Q6: =O6-P6 -> 0.046242 | R6: =((B6+N6)*$BJ$3*$BJ$4*10^-3)/$BJ$5 -> -289177.92 | S6: =((C6+N6)*$BJ$3*$BJ$4*10^-3)/$BJ$5 -> -289189.36 | T6: =((G6+N6)*$BJ$3*$BJ$4*10^-3)/$BJ$5 -> -289247.87 | U6: =((G6+N6)*$BJ$3*$BJ$4*10^-3)/$BJ$5 -> -289247.87 | V6: =((G6+P6)*$BJ$3*$BJ$4*10^-3)/$BJ$5 -> -289270.25 | W6: =((G6+P6)*$BJ$3*$BJ$4*10^-3)/$BJ$5+I6 -> -289278.62 | X6: =((G6+P6)*$BJ$3*$BJ$4*10^-3)/$BJ$5+J6 -> -289277.02 | AB6: =((G6+P6)*$BJ$3*$BJ$4*10^-3)/$BJ$5+L6 -> -289274.67 | AF6: AP-U/RB3LYP | AG6: B3//B2 + UAKS/B2 | AH6: =T93-(T81+T83)-2.3 -> 11.251606 | AI6: =-312736.8-T93-0.6 -> 20.50398 | AJ6: =AH6+AI6 -> 31.755585 | AL6: =ABS($AJ$29-AJ6) -> 2.0555855 | AZ6: exat singlet | BB6: 0 | BD6: =(BA4-BD4) -> -19.860977
A7: HO2(-) | B7: -150.87592 | C7: -150.88124 | E7: -150.91665 | G7: -150.92076 | J7: -89.26 | K7: -96.33 | N7: 0.013388 | O7: 0.017244 | P7: -0.008346 | Q7: =O7-P7 -> 0.02559 | R7: =((B7+N7)*$BJ$3*$BJ$4*10^-3)/$BJ$5 -> -94667.638 | S7: =((C7+N7)*$BJ$3*$BJ$4*10^-3)/$BJ$5 -> -94670.981 | T7: =((G7+N7)*$BJ$3*$BJ$4*10^-3)/$BJ$5 -> -94695.778 | U7: =((G7+N7)*$BJ$3*$BJ$4*10^-3)/$BJ$5 -> -94695.778 | V7: =((G7+P7)*$BJ$3*$BJ$4*10^-3)/$BJ$5 -> -94709.416 | W7: =((G7+P7)*$BJ$3*$BJ$4*10^-3)/$BJ$5+I7 -> -94709.416 | X7: =((G7+P7)*$BJ$3*$BJ$4*10^-3)/$BJ$5+J7 -> -94798.676 | Y7: =((G7+P7)*$BJ$3*$BJ$4*10^-3)/$BJ$5+K7 -> -94805.746 | Z7: =((E7+P7)*$BJ$3*$BJ$4*10^-3)/$BJ$5+K7 -> -94803.164 | AA7: =((C7+P7)*$BJ$3*$BJ$4*10^-3)/$BJ$5+K7 -> -94780.949 | AB7: =((G7+P7)*$BJ$3*$BJ$4*10^-3)/$BJ$5+L7 -> -94709.416 | AF7: AP-U/RB3LYP | AG7: B3//B2 + Bondi/B2 | AH7: =U93-(U81+U83)-2.3 -> 8.9316058 | AI7: =-312738.27-U93-0.6 -> 17.44398 | AJ7: =AH7+AI7 -> 26.375585 | AL7: =ABS($AJ$29-AJ7) -> 3.3244145 | AZ7: splitting [kCal/mol] | BA7: =(BA5-BA4) -> -23.118848 | BI7: Skodje-Thruhlar approx. for exoergic reactions
A8: H2O2 | B8: -151.47881 | C8: -151.48877 | E8: -151.52656 | G8: -151.53157 | I8: -12.15 | J8: -10 | K8: -9.18 | L8: -10.51 | N8: 0.027012 | O8: 0.03111 | P8: 0.004801 | Q8: =O8-P8 -> 0.026309 | R8: =((B8+N8)*$BJ$3*$BJ$4*10^-3)/$BJ$5 -> -95037.407 | S8: =((C8+N8)*$BJ$3*$BJ$4*10^-3)/$BJ$5 -> -95043.661 | T8: =((G8+N8)*$BJ$3*$BJ$4*10^-3)/$BJ$5 -> -95070.519 | U8: =((G8+N8)*$BJ$3*$BJ$4*10^-3)/$BJ$5 -> -95070.519 | V8: =((G8+P8)*$BJ$3*$BJ$4*10^-3)/$BJ$5 -> -95084.457 | W8: =((G8+P8)*$BJ$3*$BJ$4*10^-3)/$BJ$5+I8 -> -95096.607 | X8: =((G8+P8)*$BJ$3*$BJ$4*10^-3)/$BJ$5+J8 -> -95094.457 | Y8: =((G8+P8)*$BJ$3*$BJ$4*10^-3)/$BJ$5+K8 -> -95093.637 | Z8: =((E8+P8)*$BJ$3*$BJ$4*10^-3)/$BJ$5+K8 -> -95090.492 | AA8: =((C8+P8)*$BJ$3*$BJ$4*10^-3)/$BJ$5+K8 -> -95066.779 | AB8: =((G8+P8)*$BJ$3*$BJ$4*10^-3)/$BJ$5+L8 -> -95094.967 | AF8: AP-U/RB3LYP | AG8: B3//B2 + Pauling/B2 | AH8: =V93-(V81+V83)-2.3 -> 9.1616058 | AI8: =-312738.15-V93-0.6 -> 17.05398 | AJ8: =AH8+AI8 -> 26.215585 | AL8: =ABS($AJ$29-AJ8) -> 3.4844145 | BI8: v [1/cm] | BJ8: 2030
A9: OOH2 | B9: -151.40366 | C9: -151.41276 | E9: -151.45071 | G9: -151.45574 | J9: -26.73 | K9: -25.25 | N9: 0.026577 | O9: 0.030581 | P9: 0.004304 | Q9: =O9-P9 -> 0.026277 | R9: =((B9+N9)*$BJ$3*$BJ$4*10^-3)/$BJ$5 -> -94990.525 | S9: =((C9+N9)*$BJ$3*$BJ$4*10^-3)/$BJ$5 -> -94996.235 | T9: =((G9+N9)*$BJ$3*$BJ$4*10^-3)/$BJ$5 -> -95023.206 | U9: =((G9+N9)*$BJ$3*$BJ$4*10^-3)/$BJ$5 -> -95023.206 | V9: =((G9+P9)*$BJ$3*$BJ$4*10^-3)/$BJ$5 -> -95037.182 | W9: =((G9+P9)*$BJ$3*$BJ$4*10^-3)/$BJ$5+I9 -> -95037.182 | X9: =((G9+P9)*$BJ$3*$BJ$4*10^-3)/$BJ$5+J9 -> -95063.912 | Y9: =((G9+P9)*$BJ$3*$BJ$4*10^-3)/$BJ$5+K9 -> -95062.432 | Z9: =((E9+P9)*$BJ$3*$BJ$4*10^-3)/$BJ$5+K9 -> -95059.277 | AA9: =((C9+P9)*$BJ$3*$BJ$4*10^-3)/$BJ$5+K9 -> -95035.461 | AB9: =((G9+P9)*$BJ$3*$BJ$4*10^-3)/$BJ$5+L9 -> -95037.182 | AF9: BS-U/RM052X | AG9: B5//B2 | AH9: =S76-(S66+S68)-2.3 -> 0.59043765 | AI9: =S74-S76-0.7 -> 43.481826 | AJ9: =AH9+AI9 -> 44.072264 | AL9: =ABS($AJ$29-AJ9) -> 14.372264 | BI9: ∆(V#+zpve) [kJ/mol] | BJ9: 100
A10: NA(+)H2O2 | C10: -313.61187 | E10: -313.6534 | G10: -313.65785 | J10: -62.52 | K10: -61.77 | N10: 0.028973 | O10: 0.034322 | P10: 0.002644 | Q10: =O10-P10 -> 0.031678 | R10: =((B10+N10)*$BJ$3*$BJ$4*10^-3)/$BJ$5 -> 18.180826 | S10: =((C10+N10)*$BJ$3*$BJ$4*10^-3)/$BJ$5 -> -196776.18 | T10: =((G10+N10)*$BJ$3*$BJ$4*10^-3)/$BJ$5 -> -196805.03 | U10: =((G10+N10)*$BJ$3*$BJ$4*10^-3)/$BJ$5 -> -196805.03 | V10: =((G10+P10)*$BJ$3*$BJ$4*10^-3)/$BJ$5 -> -196821.56 | W10: =((G10+P10)*$BJ$3*$BJ$4*10^-3)/$BJ$5+I10 -> -196821.56 | X10: =((G10+P10)*$BJ$3*$BJ$4*10^-3)/$BJ$5+J10 -> -196884.08 | Y10: =((G10+P10)*$BJ$3*$BJ$4*10^-3)/$BJ$5+K10 -> -196883.33 | Z10: =((E10+P10)*$BJ$3*$BJ$4*10^-3)/$BJ$5+K10 -> -196880.53 | AA10: =((C10+P10)*$BJ$3*$BJ$4*10^-3)/$BJ$5+K10 -> -196854.47 | AB10: =((G10+P10)*$BJ$3*$BJ$4*10^-3)/$BJ$5+L10 -> -196821.56 | AF10: AP-U/RM052X | AG10: B5//B2 | AH10: =S76-(S66+S68)-2.3 -> 0.59043765 | AI10: =-312665.13-S76-0.7 -> 34.395164 | AJ10: =AH10+AI10 -> 34.985602 | AL10: =ABS($AJ$29-AJ10) -> 5.2856018 | AZ10: =BA4-BA5 -> 23.118848 | BI10: T [K] | BJ10: 700
A11: NA(+)OOH2 | C11: -313.55657 | E11: -313.59854 | G11: -313.6032 | J11: -68.73 | K11: -67.2 | N11: 0.028555 | O11: 0.034099 | P11: 0.001817 | Q11: =O11-P11 -> 0.032282 | R11: =((B11+N11)*$BJ$3*$BJ$4*10^-3)/$BJ$5 -> 17.918528 | S11: =((C11+N11)*$BJ$3*$BJ$4*10^-3)/$BJ$5 -> -196741.74 | T11: =((G11+N11)*$BJ$3*$BJ$4*10^-3)/$BJ$5 -> -196771 | U11: =((G11+N11)*$BJ$3*$BJ$4*10^-3)/$BJ$5 -> -196771 | V11: =((G11+P11)*$BJ$3*$BJ$4*10^-3)/$BJ$5 -> -196787.78 | W11: =((G11+P11)*$BJ$3*$BJ$4*10^-3)/$BJ$5+I11 -> -196787.78 | X11: =((G11+P11)*$BJ$3*$BJ$4*10^-3)/$BJ$5+J11 -> -196856.51 | Y11: =((G11+P11)*$BJ$3*$BJ$4*10^-3)/$BJ$5+K11 -> -196854.98 | Z11: =((E11+P11)*$BJ$3*$BJ$4*10^-3)/$BJ$5+K11 -> -196852.06 | AA11: =((C11+P11)*$BJ$3*$BJ$4*10^-3)/$BJ$5+K11 -> -196825.72 | AB11: =((G11+P11)*$BJ$3*$BJ$4*10^-3)/$BJ$5+L11 -> -196787.78 | AF11: BS-U/RM052X | AG11: B5//B2 + Bondi/B2 | AH11: =U76-(U66+U68)-2.3 -> 8.9304376 | AI11: =U74-U76-0.7 -> 37.881826 | AJ11: =AH11+AI11 -> 46.812264 | AL11: =ABS($AJ$29-AJ11) -> 17.112264 | BI11: h(bar) [J*s] | BJ11: =6.62606896E-34/(2*BJ14) -> 1.0545716e-34 | BN11: =BJ10*BJ13/BJ12 -> 1.458565e+13
A12: H2O2*2H2O | B12: -304.28986 | C12: -304.31996 | E12: -304.39455 | G12: -304.40422 | J12: -15.46 | K12: -14.27 | N12: 0.078831 | O12: 0.087912 | P12: 0.047462 | Q12: =O12-P12 -> 0.04045 | R12: =((B12+N12)*$BJ$3*$BJ$4*10^-3)/$BJ$5 -> -190895.24 | S12: =((C12+N12)*$BJ$3*$BJ$4*10^-3)/$BJ$5 -> -190914.14 | T12: =((G12+N12)*$BJ$3*$BJ$4*10^-3)/$BJ$5 -> -190967.01 | U12: =((G12+N12)*$BJ$3*$BJ$4*10^-3)/$BJ$5 -> -190967.01 | V12: =((G12+P12)*$BJ$3*$BJ$4*10^-3)/$BJ$5 -> -190986.69 | W12: =((G12+P12)*$BJ$3*$BJ$4*10^-3)/$BJ$5+I12 -> -190986.69 | X12: =((G12+P12)*$BJ$3*$BJ$4*10^-3)/$BJ$5+J12 -> -191002.15 | Y12: =((G12+P12)*$BJ$3*$BJ$4*10^-3)/$BJ$5+K12 -> -191000.96 | Z12: =((E12+P12)*$BJ$3*$BJ$4*10^-3)/$BJ$5+K12 -> -190994.89 | AA12: =((C12+P12)*$BJ$3*$BJ$4*10^-3)/$BJ$5+K12 -> -190948.09 | AB12: =((G12+P12)*$BJ$3*$BJ$4*10^-3)/$BJ$5+L12 -> -190986.69 | AF12: AP-U/RM052X | AG12: B5//B2 + UAKS/B2 | AH12: =T76-(T66+T68)-2.3 -> 13.230438 | AI12: =-312677.43-U76-0.7 -> 30.125164 | AJ12: =AH12+AI12 -> 43.355602 | AL12: =ABS($AJ$29-AJ12) -> 13.655602 | BA12: =-414300.37-X39 -> 29.974539 | BI12: h [J*s] | BJ12: 6.626069e-34
A13: H2O2*2H2O_TS | B13: -304.23209 | C13: -304.26508 | E13: -304.33948 | G13: -304.34761 | J13: -23.32 | K13: -21.54 | M13: 953.33 | N13: 0.072533 | O13: 0.079238 | P13: 0.043482 | Q13: =O13-P13 -> 0.035756 | R13: =((B13+N13)*$BJ$3*$BJ$4*10^-3)/$BJ$5 -> -190862.95 | S13: =((C13+N13)*$BJ$3*$BJ$4*10^-3)/$BJ$5 -> -190883.64 | T13: =((G13+N13)*$BJ$3*$BJ$4*10^-3)/$BJ$5 -> -190935.43 | U13: =((G13+N13)*$BJ$3*$BJ$4*10^-3)/$BJ$5 -> -190935.43 | V13: =((G13+P13)*$BJ$3*$BJ$4*10^-3)/$BJ$5 -> -190953.66 | W13: =((G13+P13)*$BJ$3*$BJ$4*10^-3)/$BJ$5+I13 -> -190953.66 | X13: =((G13+P13)*$BJ$3*$BJ$4*10^-3)/$BJ$5+J13 -> -190976.98 | Y13: =((G13+P13)*$BJ$3*$BJ$4*10^-3)/$BJ$5+K13 -> -190975.2 | Z13: =((E13+P13)*$BJ$3*$BJ$4*10^-3)/$BJ$5+K13 -> -190970.1 | AA13: =((C13+P13)*$BJ$3*$BJ$4*10^-3)/$BJ$5+K13 -> -190923.41 | AB13: =((G13+P13)*$BJ$3*$BJ$4*10^-3)/$BJ$5+L13 -> -190953.66 | AF13: AP-U/RM052X | AG13: B5//B2 + Bondi/B2 | AH13: =U76-(U66+U68)-2.3 -> 8.9304376 | AI13: =-312678.34-U76-0.7 -> 29.215164 | AJ13: =AH13+AI13 -> 38.145602 | AL13: =ABS($AJ$29-AJ13) -> 8.4456018 | BE13: =1.89+0.4 -> 2.29 | BI13: kb [J/K] | BJ13: 1.3806503e-23
A14: Wateroxide*2H2O_A | B14: -304.23834 | C14: -304.26775 | E14: -304.34278 | G14: -304.35177 | J14: -23.99 | K14: -22.01 | N14: 0.078828 | O14: 0.08698 | P14: 0.048177 | Q14: =O14-P14 -> 0.038803 | R14: =((B14+N14)*$BJ$3*$BJ$4*10^-3)/$BJ$5 -> -190862.92 | S14: =((C14+N14)*$BJ$3*$BJ$4*10^-3)/$BJ$5 -> -190881.37 | T14: =((G14+N14)*$BJ$3*$BJ$4*10^-3)/$BJ$5 -> -190934.1 | U14: =((G14+N14)*$BJ$3*$BJ$4*10^-3)/$BJ$5 -> -190934.1 | V14: =((G14+P14)*$BJ$3*$BJ$4*10^-3)/$BJ$5 -> -190953.33 | W14: =((G14+P14)*$BJ$3*$BJ$4*10^-3)/$BJ$5+I14 -> -190953.33 | X14: =((G14+P14)*$BJ$3*$BJ$4*10^-3)/$BJ$5+J14 -> -190977.32 | Y14: =((G14+P14)*$BJ$3*$BJ$4*10^-3)/$BJ$5+K14 -> -190975.34 | Z14: =((E14+P14)*$BJ$3*$BJ$4*10^-3)/$BJ$5+K14 -> -190969.7 | AA14: =((C14+P14)*$BJ$3*$BJ$4*10^-3)/$BJ$5+K14 -> -190922.61 | AB14: =((G14+P14)*$BJ$3*$BJ$4*10^-3)/$BJ$5+L14 -> -190953.33 | AF14: AP-U/RM052X | AG14: B5//B2 + Pauling/B2 | AH14: =V76-(V66+V68)-2.3 -> 8.6404376 | AI14: =-312677.79-V76-0.7 -> 29.205164 | AJ14: =AH14+AI14 -> 37.845602 | AL14: =ABS($AJ$29-AJ14) -> 8.1456018 | BA14: =BD4-(X3+X8)-2.89 -> -192909.29 | BI14: Pi | BJ14: 3.1415927
A15: H2O2*4H2O | B15: -457.10376 | C15: -457.15389 | E15: -457.26536 | G15: -457.27954 | J15: -19.12 | K15: -17.5 | N15: 0.130462 | O15: 0.144709 | P15: 0.090952 | Q15: =O15-P15 -> 0.053757 | R15: =((B15+N15)*$BJ$3*$BJ$4*10^-3)/$BJ$5 -> -286754.98 | S15: =((C15+N15)*$BJ$3*$BJ$4*10^-3)/$BJ$5 -> -286786.44 | T15: =((G15+N15)*$BJ$3*$BJ$4*10^-3)/$BJ$5 -> -286865.29 | U15: =((G15+N15)*$BJ$3*$BJ$4*10^-3)/$BJ$5 -> -286865.29 | V15: =((G15+P15)*$BJ$3*$BJ$4*10^-3)/$BJ$5 -> -286890.08 | W15: =((G15+P15)*$BJ$3*$BJ$4*10^-3)/$BJ$5+I15 -> -286890.08 | X15: =((G15+P15)*$BJ$3*$BJ$4*10^-3)/$BJ$5+J15 -> -286909.2 | Y15: =((G15+P15)*$BJ$3*$BJ$4*10^-3)/$BJ$5+K15 -> -286907.58 | Z15: =((E15+P15)*$BJ$3*$BJ$4*10^-3)/$BJ$5+K15 -> -286898.69 | AA15: =((C15+P15)*$BJ$3*$BJ$4*10^-3)/$BJ$5+K15 -> -286828.73 | AB15: =((G15+P15)*$BJ$3*$BJ$4*10^-3)/$BJ$5+L15 -> -286890.08 | AF15: BS-U/RM05 | AG15: B5//B2 | AH15: =V27-(V3+V8)-2.3 -> 2.7524933 | AI15: =V25-V27-0.6 -> 33.414478 | AJ15: =AH15+AI15 -> 36.166972 | AL15: =ABS($AJ$29-AJ15) -> 6.4669715 | BI15: R [J/mol*K] | BJ15: 8.314472
A16: H2O2*5H2O | B16: -533.50813 | C16: -533.56792 | E16: -533.69806 | G16: -533.71446 | J16: -20.47 | K16: -18.37 | N16: 0.1559 | O16: 0.172991 | P16: 0.112566 | Q16: =O16-P16 -> 0.060425 | R16: =((B16+N16)*$BJ$3*$BJ$4*10^-3)/$BJ$5 -> -334683.48 | S16: =((C16+N16)*$BJ$3*$BJ$4*10^-3)/$BJ$5 -> -334721 | T16: =((G16+N16)*$BJ$3*$BJ$4*10^-3)/$BJ$5 -> -334812.95 | U16: =((G16+N16)*$BJ$3*$BJ$4*10^-3)/$BJ$5 -> -334812.95 | V16: =((G16+P16)*$BJ$3*$BJ$4*10^-3)/$BJ$5 -> -334840.14 | W16: =((G16+P16)*$BJ$3*$BJ$4*10^-3)/$BJ$5+I16 -> -334840.14 | X16: =((G16+P16)*$BJ$3*$BJ$4*10^-3)/$BJ$5+J16 -> -334860.61 | Y16: =((G16+P16)*$BJ$3*$BJ$4*10^-3)/$BJ$5+K16 -> -334858.51 | Z16: =((E16+P16)*$BJ$3*$BJ$4*10^-3)/$BJ$5+K16 -> -334848.22 | AA16: =((C16+P16)*$BJ$3*$BJ$4*10^-3)/$BJ$5+K16 -> -334766.56 | AB16: =((G16+P16)*$BJ$3*$BJ$4*10^-3)/$BJ$5+L16 -> -334840.14 | AF16: AP-U/RM05 | AG16: B5//B2 | AH16: =V27-(V3+V8)-2.3 -> 2.7524933 | AI16: =-312493.14-V27-0.6 -> 25.818313 | AJ16: =AH16+AI16 -> 28.570807 | AL16: =ABS($AJ$29-AJ16) -> 1.1291933 | BI16: Na [1/mol] | BJ16: 6.02214e+23
A17: Wateroxide*4H2O_TS | B17: -457.05613 | C17: -457.10979 | E17: -457.22087 | G17: -457.2332 | J17: -22.47 | K17: -20.78 | M17: 1119.76 | N17: 0.123908 | O17: 0.135634 | P17: 0.087053 | Q17: =O17-P17 -> 0.048581 | R17: =((B17+N17)*$BJ$3*$BJ$4*10^-3)/$BJ$5 -> -286729.21 | S17: =((C17+N17)*$BJ$3*$BJ$4*10^-3)/$BJ$5 -> -286762.88 | T17: =((G17+N17)*$BJ$3*$BJ$4*10^-3)/$BJ$5 -> -286840.32 | U17: =((G17+N17)*$BJ$3*$BJ$4*10^-3)/$BJ$5 -> -286840.32 | V17: =((G17+P17)*$BJ$3*$BJ$4*10^-3)/$BJ$5 -> -286863.45 | W17: =((G17+P17)*$BJ$3*$BJ$4*10^-3)/$BJ$5+I17 -> -286863.45 | X17: =((G17+P17)*$BJ$3*$BJ$4*10^-3)/$BJ$5+J17 -> -286885.92 | Y17: =((G17+P17)*$BJ$3*$BJ$4*10^-3)/$BJ$5+K17 -> -286884.23 | Z17: =((E17+P17)*$BJ$3*$BJ$4*10^-3)/$BJ$5+K17 -> -286876.49 | AA17: =((C17+P17)*$BJ$3*$BJ$4*10^-3)/$BJ$5+K17 -> -286806.79 | AB17: =((G17+P17)*$BJ$3*$BJ$4*10^-3)/$BJ$5+L17 -> -286863.45 | AF17: BS-U/RM05 | AG17: B5//B2 + Bondi/B2 | AH17: =X27-(X3+X8)-2.3 -> 9.3324933 | AI17: =X25-X27-0.6 -> 27.304478 | AJ17: =AH17+AI17 -> 36.636972 | AL17: =ABS($AJ$29-AJ17) -> 6.9369715 | BA17: RC-(BnOH+H2O2) | BB17: TS-RC | BC17: sum | BI17: c [cm/s] | BJ17: 29979245800
A18: Wateroxide*4H2O | B18: -457.06761 | C18: -457.11701 | E18: -457.22894 | G18: -457.24219 | J18: -22.43 | K18: -20.52 | N18: 0.130855 | O18: 0.143941 | P18: 0.091985 | Q18: =O18-P18 -> 0.051956 | R18: =((B18+N18)*$BJ$3*$BJ$4*10^-3)/$BJ$5 -> -286732.05 | S18: =((C18+N18)*$BJ$3*$BJ$4*10^-3)/$BJ$5 -> -286763.05 | T18: =((G18+N18)*$BJ$3*$BJ$4*10^-3)/$BJ$5 -> -286841.6 | U18: =((G18+N18)*$BJ$3*$BJ$4*10^-3)/$BJ$5 -> -286841.6 | V18: =((G18+P18)*$BJ$3*$BJ$4*10^-3)/$BJ$5 -> -286865.99 | W18: =((G18+P18)*$BJ$3*$BJ$4*10^-3)/$BJ$5+I18 -> -286865.99 | X18: =((G18+P18)*$BJ$3*$BJ$4*10^-3)/$BJ$5+J18 -> -286888.42 | Y18: =((G18+P18)*$BJ$3*$BJ$4*10^-3)/$BJ$5+K18 -> -286886.51 | Z18: =((E18+P18)*$BJ$3*$BJ$4*10^-3)/$BJ$5+K18 -> -286878.2 | AA18: =((C18+P18)*$BJ$3*$BJ$4*10^-3)/$BJ$5+K18 -> -286807.97 | AB18: =((G18+P18)*$BJ$3*$BJ$4*10^-3)/$BJ$5+L18 -> -286865.99 | AF18: AP-U/RM05 | AG18: B5//B2 + Bondi/B2 | AH18: =X27-(X3+X8)-2.3 -> 9.3324933 | AI18: =-312507.3-X27-0.6 -> 20.128313 | AJ18: =AH18+AI18 -> 29.460807 | AL18: =ABS($AJ$29-AJ18) -> 0.23919327 | AN18: =X30-(X3+X7)-1.9 -> 9.5194904 | AO18: =-312210.94-X30-0.2 -> 21.320733 | AP18: =AN18+AO18 -> 30.840224 | AR18: =X21-(X3+X20)-1.9 -> -0.49738849 | AS18: =X22-X21-0.1 -> 28.359468 | AT18: =AR18+AS18 -> 27.86208 | AZ18: high | BA18: =X27-(X3+X8)-1.89+0.4 -> 10.142493 | BB18: =-312507.3-X27 -> 20.728313 | BC18: =BB18+BA18-0.6 -> 30.270807 | BI18: a=(2*pi/h*v*c) [1/J] | BJ18: =((2*BJ14)/(BJ12*BJ8*BJ17)) -> 1.5581425e+20
A19: Wateroxide*5H2O | B19: -533.47367 | C19: -533.53327 | E19: -533.66372 | G19: -533.67931 | J19: -22.86 | K19: -20.83 | N19: 0.155833 | O19: 0.171938 | P19: 0.113207 | Q19: =O19-P19 -> 0.058731 | R19: =((B19+N19)*$BJ$3*$BJ$4*10^-3)/$BJ$5 -> -334661.89 | S19: =((C19+N19)*$BJ$3*$BJ$4*10^-3)/$BJ$5 -> -334699.29 | T19: =((G19+N19)*$BJ$3*$BJ$4*10^-3)/$BJ$5 -> -334790.94 | U19: =((G19+N19)*$BJ$3*$BJ$4*10^-3)/$BJ$5 -> -334790.94 | V19: =((G19+P19)*$BJ$3*$BJ$4*10^-3)/$BJ$5 -> -334817.68 | W19: =((G19+P19)*$BJ$3*$BJ$4*10^-3)/$BJ$5+I19 -> -334817.68 | X19: =((G19+P19)*$BJ$3*$BJ$4*10^-3)/$BJ$5+J19 -> -334840.54 | Y19: =((G19+P19)*$BJ$3*$BJ$4*10^-3)/$BJ$5+K19 -> -334838.51 | Z19: =((E19+P19)*$BJ$3*$BJ$4*10^-3)/$BJ$5+K19 -> -334828.73 | AA19: =((C19+P19)*$BJ$3*$BJ$4*10^-3)/$BJ$5+K19 -> -334746.87 | AB19: =((G19+P19)*$BJ$3*$BJ$4*10^-3)/$BJ$5+L19 -> -334817.68 | AF19: AP-U/RM05 | AG19: B5//B2 + UAKS/B2 | AH19: =W27-(W3+W8)-2.3 -> 11.222493 | AI19: =-312506.46-W27-0.6 -> 23.108313 | AJ19: =AH19+AI19 -> 34.330807 | AL19: =ABS($AJ$29-AJ19) -> 4.6308067 | AZ19: medium | BA19: =X48-(X4+X8)-1.89+0.4 -> 9.0425075 | BB19: =-312509.16-X48 -> 21.52456 | BC19: =BB19+BA19-0.7 -> 29.867068 | BI19: b=(1/(kb*T)) [1/J] | BJ19: =(1/(BJ13*BJ10)) -> 1.0347091e+20
A20: HO2Na | B20: -313.20313 | C20: -313.20815 | G20: -313.25239 | I20: -32.66 | J20: -22.81 | L20: -43.76 | N20: 0.015633 | O20: 0.020765 | P20: -0.010347 | Q20: =O20-P20 -> 0.031112 | R20: =((B20+N20)*$BJ$3*$BJ$4*10^-3)/$BJ$5 -> -196528.06 | S20: =((C20+N20)*$BJ$3*$BJ$4*10^-3)/$BJ$5 -> -196531.21 | T20: =((G20+N20)*$BJ$3*$BJ$4*10^-3)/$BJ$5 -> -196558.97 | U20: =((G20+N20)*$BJ$3*$BJ$4*10^-3)/$BJ$5 -> -196558.97 | V20: =((G20+P20)*$BJ$3*$BJ$4*10^-3)/$BJ$5 -> -196575.28 | W20: =((G20+P20)*$BJ$3*$BJ$4*10^-3)/$BJ$5+I20 -> -196607.94 | X20: =((G20+P20)*$BJ$3*$BJ$4*10^-3)/$BJ$5+J20 -> -196598.09 | Y20: =((G20+P20)*$BJ$3*$BJ$4*10^-3)/$BJ$5+K20 -> -196575.28 | AB20: =((G20+P20)*$BJ$3*$BJ$4*10^-3)/$BJ$5+L20 -> -196619.04 | AF20: AP-U/RM05 | AG20: B5//B2 + Paulin/gB2 | AH20: =AB27-(AB3+AB8)-2.3 -> 9.9324933 | AI20: =-312506.87-AB27-0.6 -> 19.818313 | AJ20: =AH20+AI20 -> 29.750807 | AL20: =ABS($AJ$29-AJ20) -> 0.050806734 | AZ20: low | BA20: =X51-(X5+X8)-1.89+0.4 -> 10.539945 | BB20: =-312507.36-X51 -> 21.568182 | BC20: =BB20+BA20-0.8 -> 31.308127 | BI20: k(T) a>b | BJ20: =((BJ19*BJ14)/BJ18)/SIN((BJ19*BJ14)/BJ18)-(BJ19/(BJ18-BJ19))*EXP((BJ19-BJ18)*((BJ9*1000/BJ16))) -> 2.397401
A21: TS1(NA)_BnOH_RC | B21: -659.77673 | C21: -659.79723 | G21: -659.90536 | I21: -20.27 | J21: -15.18 | L21: -26.66 | N21: 0.151826 | O21: 0.165055 | P21: 0.111605 | Q21: =O21-P21 -> 0.05345 | R21: =((B21+N21)*$BJ$3*$BJ$4*10^-3)/$BJ$5 -> -413920.75 | S21: =((C21+N21)*$BJ$3*$BJ$4*10^-3)/$BJ$5 -> -413933.62 | T21: =((G21+N21)*$BJ$3*$BJ$4*10^-3)/$BJ$5 -> -414001.47 | U21: =((G21+N21)*$BJ$3*$BJ$4*10^-3)/$BJ$5 -> -414001.47 | V21: =((G21+P21)*$BJ$3*$BJ$4*10^-3)/$BJ$5 -> -414026.71 | W21: =((G21+P21)*$BJ$3*$BJ$4*10^-3)/$BJ$5+I21 -> -414046.98 | X21: =((G21+P21)*$BJ$3*$BJ$4*10^-3)/$BJ$5+J21 -> -414041.89 | Y21: =((G21+P21)*$BJ$3*$BJ$4*10^-3)/$BJ$5+K21 -> -414026.71 | AB21: =((G21+P21)*$BJ$3*$BJ$4*10^-3)/$BJ$5+L21 -> -414053.37 | AF21: AP-U/RM05 | AG21: B5//ONIOM/B2 + Bondi/B2 | AH21: =X48-(X4+X8)-2.3 -> 8.2325075 | AI21: =-312509.68-X48-0.7 -> 20.30456 | AJ21: =AH21+AI21 -> 28.537068 | AK21: =ABS($AI$18-AI21) -> 0.17624679 | AL21: =ABS($AJ$29-AJ21) -> 1.1629322 | AN21: =X54-(X4+X7)-1.9 -> 9.8240116 | AO21: =-312213.33-X54-0.1 -> 20.282473 | AP21: =AN21+AO21 -> 30.106485 | AQ21: =ABS($AO$18-AO21) -> 1.0382601 | BI21: RTln(k(T)) a>b [kCal/mol] | BJ21: =(BJ15*BJ10*LN(BJ20)/1000)/BJ5 -> 1.2163088
A22: TS1(NA)_BnOH_TS | B22: -659.73066 | C22: -659.75135 | G22: -659.8595 | I22: -21.75 | J22: -12.43 | L22: -25.08 | M22: 504.28 | N22: 0.146509 | O22: 0.159354 | P22: 0.106714 | Q22: =O22-P22 -> 0.05264 | R22: =((B22+N22)*$BJ$3*$BJ$4*10^-3)/$BJ$5 -> -413895.18 | S22: =((C22+N22)*$BJ$3*$BJ$4*10^-3)/$BJ$5 -> -413908.16 | T22: =((G22+N22)*$BJ$3*$BJ$4*10^-3)/$BJ$5 -> -413976.03 | U22: =((G22+N22)*$BJ$3*$BJ$4*10^-3)/$BJ$5 -> -413976.03 | V22: =((G22+P22)*$BJ$3*$BJ$4*10^-3)/$BJ$5 -> -414001 | W22: =((G22+P22)*$BJ$3*$BJ$4*10^-3)/$BJ$5+I22 -> -414022.75 | X22: =((G22+P22)*$BJ$3*$BJ$4*10^-3)/$BJ$5+J22 -> -414013.43 | Y22: =((G22+P22)*$BJ$3*$BJ$4*10^-3)/$BJ$5+K22 -> -414001 | AB22: =((G22+P22)*$BJ$3*$BJ$4*10^-3)/$BJ$5+L22 -> -414026.08 | AF22: AP-U/RM05 | AG22: B5//ONIOM/B2 + Bond1/B1 | AH22: =Y48-(Y4+Y8)-2.3 -> 7.5525075 | AI22: =-312507.68-Y48-0.7 -> 21.32456 | AJ22: =AH22+AI22 -> 28.877068 | AK22: =ABS($AI$18-AI22) -> 1.1962468 | AL22: =ABS($AJ$29-AJ22) -> 0.8229322 | AN22: =Y54-(Y4+Y7)-1.9 -> 14.404012 | AO22: =-312214.28-Y54-0.1 -> 20.982473 | AP22: =AN22+AO22 -> 35.386485 | AQ22: =ABS($AO$18-AO22) -> 0.33826015 | BI22: k(T) a<b | BJ22: =(BJ19/(BJ19-BJ18))*(EXP((BJ19-BJ18)*((BJ9)*1000/BJ16))-1) -> 1.9764411
A23: TS1(NA)_MeOBnOH_RC | B23: -774.24478 | C23: -774.26771 | G23: -774.40353 | I23: -21.67 | J23: -16.38 | L23: -28.18 | N23: 0.185049 | O23: 0.200798 | P23: 0.141478 | Q23: =O23-P23 -> 0.05932 | R23: =((B23+N23)*$BJ$3*$BJ$4*10^-3)/$BJ$5 -> -485729.67 | S23: =((C23+N23)*$BJ$3*$BJ$4*10^-3)/$BJ$5 -> -485744.05 | T23: =((G23+N23)*$BJ$3*$BJ$4*10^-3)/$BJ$5 -> -485829.28 | U23: =((G23+N23)*$BJ$3*$BJ$4*10^-3)/$BJ$5 -> -485829.28 | V23: =((G23+P23)*$BJ$3*$BJ$4*10^-3)/$BJ$5 -> -485856.62 | W23: =((G23+P23)*$BJ$3*$BJ$4*10^-3)/$BJ$5+I23 -> -485878.29 | X23: =((G23+P23)*$BJ$3*$BJ$4*10^-3)/$BJ$5+J23 -> -485873 | Y23: =((G23+P23)*$BJ$3*$BJ$4*10^-3)/$BJ$5+K23 -> -485856.62 | AB23: =((G23+P23)*$BJ$3*$BJ$4*10^-3)/$BJ$5+L23 -> -485884.8 | AF23: AP-U/RM05 | AG23: B4//ONIOM/B2 + Bondi/B1 | AH23: =Z48-(Z4+Z8)-2.3 -> 7.3208901 | AI23: =-312497.81-Z48-0.7 -> 20.829066 | AJ23: =AH23+AI23 -> 28.149956 | AK23: =ABS($AI$18-AI23) -> 0.70075291 | AL23: =ABS($AJ$29-AJ23) -> 1.5500435 | AN23: =Z54-(Z4+Z7)-1.9 -> 14.063132 | AO23: =-312205.07-Z54-0.1 -> 20.499183 | AP23: =AN23+AO23 -> 34.562315 | AQ23: =ABS($AO$18-AO23) -> 0.8215504 | BI23: RTln(k(T)) a<b [kCal/mol] | BJ23: =(BJ15*BJ10*LN(BJ22)/1000)/BJ5 -> 0.94771562
A24: TS1(NA)_MeOBnOH_TS | B24: -774.19798 | C24: -774.22102 | G24: -774.35691 | I24: -23.71 | J24: -14.32 | L24: -27.08 | M24: 500.6 | N24: 0.179645 | O24: 0.195146 | P24: 0.136147 | Q24: =O24-P24 -> 0.058999 | R24: =((B24+N24)*$BJ$3*$BJ$4*10^-3)/$BJ$5 -> -485703.69 | S24: =((C24+N24)*$BJ$3*$BJ$4*10^-3)/$BJ$5 -> -485718.15 | T24: =((G24+N24)*$BJ$3*$BJ$4*10^-3)/$BJ$5 -> -485803.42 | U24: =((G24+N24)*$BJ$3*$BJ$4*10^-3)/$BJ$5 -> -485803.42 | V24: =((G24+P24)*$BJ$3*$BJ$4*10^-3)/$BJ$5 -> -485830.72 | W24: =((G24+P24)*$BJ$3*$BJ$4*10^-3)/$BJ$5+I24 -> -485854.43 | X24: =((G24+P24)*$BJ$3*$BJ$4*10^-3)/$BJ$5+J24 -> -485845.04 | Y24: =((G24+P24)*$BJ$3*$BJ$4*10^-3)/$BJ$5+K24 -> -485830.72 | AB24: =((G24+P24)*$BJ$3*$BJ$4*10^-3)/$BJ$5+L24 -> -485857.8 | AF24: AP-U/RM05 | AG24: B3//ONIOM/B2 + Bondi/B1 | AH24: =AA48-(AA4+AA8)-2.3 -> 6.7834265 | AI24: =-312440.82-AA48-0.7 -> 20.93559 | AJ24: =AH24+AI24 -> 27.719016 | AK24: =ABS($AI$18-AI24) -> 0.80727618 | AL24: =ABS($AJ$29-AJ24) -> 1.9809838 | AN24: =AA54-(AA4+AA7)-1.9 -> 14.925309 | AO24: =-312148.72-AA54-0.1 -> 20.063974 | AP24: =AN24+AO24 -> 34.989283 | AQ24: =ABS($AO$18-AO24) -> 1.2567592 | BI24: Wigner approx. Condition: h*v<<kb*T
A25: BS_U_TS1 | C25: -497.98552 | D25: 0.5763 | G25: -498.09184 | H25: 0.5804 | I25: -13.43 | J25: -14.58 | L25: -14.34 | M25: 1391.38 | N25: 0.153274 | O25: 0.165836 | P25: 0.114272 | Q25: =O25-P25 -> 0.051564 | R25: =((B25+N25)*$BJ$3*$BJ$4*10^-3)/$BJ$5 -> 96.180858 | S25: =((C25+N25)*$BJ$3*$BJ$4*10^-3)/$BJ$5 -> -312394.36 | T25: =((G25+N25)*$BJ$3*$BJ$4*10^-3)/$BJ$5 -> -312461.07 | U25: =((G25+N25)*$BJ$3*$BJ$4*10^-3)/$BJ$5 -> -312461.07 | V25: =((G25+P25)*$BJ$3*$BJ$4*10^-3)/$BJ$5 -> -312485.54 | W25: =((G25+P25)*$BJ$3*$BJ$4*10^-3)/$BJ$5+I25 -> -312498.97 | X25: =((G25+P25)*$BJ$3*$BJ$4*10^-3)/$BJ$5+J25 -> -312500.12 | Y25: =((G25+P25)*$BJ$3*$BJ$4*10^-3)/$BJ$5+K25 -> -312485.54 | AB25: =((G25+P25)*$BJ$3*$BJ$4*10^-3)/$BJ$5+L25 -> -312499.88 | AF25: AP-U/RM05 | AG25: B5//ONIOM/B1 + Bond/iB2 | AH25: =X51-(X5+X8)-2.3 -> 9.7299452 | AI25: =-312508.25-X51-0.8 -> 19.878182 | AJ25: =AH25+AI25 -> 29.608127 | AK25: =ABS($AI$18-AI25) -> 0.25013139 | AL25: =ABS($AJ$29-AJ25) -> 0.091872744 | AN25: =X57-(X5+X7)-1.9 -> 10.50969 | AO25: =-312213.97-X57-0.1 -> 18.697855 | AP25: =AN25+AO25 -> 29.207544 | AQ25: =ABS($AO$18-AO25) -> 2.6228786 | BI25: k(T) | BJ25: =1+(1/24)*(BJ12*BJ8*BJ17/(BJ10*BJ13))^2 -> 1.7253885
A26: BS_U_TS1 (T SP) | C26: -497.95624 | E26: -498.04655 | G26: -498.06223 | I26: -13.69 | J26: -15.61 | K26: -12.83 | L26: -15.83 | N26: 0.153274 | O26: 0.165836 | P26: 0.114272 | Q26: =O26-P26 -> 0.051564 | R26: =((B26+N26)*$BJ$3*$BJ$4*10^-3)/$BJ$5 -> 96.180858 | S26: =((C26+N26)*$BJ$3*$BJ$4*10^-3)/$BJ$5 -> -312375.98 | T26: =((G26+N26)*$BJ$3*$BJ$4*10^-3)/$BJ$5 -> -312442.49 | U26: =((G26+N26)*$BJ$3*$BJ$4*10^-3)/$BJ$5 -> -312442.49 | V26: =((G26+P26)*$BJ$3*$BJ$4*10^-3)/$BJ$5 -> -312466.96 | W26: =((G26+P26)*$BJ$3*$BJ$4*10^-3)/$BJ$5+I26 -> -312480.65 | X26: =((G26+P26)*$BJ$3*$BJ$4*10^-3)/$BJ$5+J26 -> -312482.57 | Y26: =((G26+P26)*$BJ$3*$BJ$4*10^-3)/$BJ$5+K26 -> -312479.79 | AB26: =((G26+P26)*$BJ$3*$BJ$4*10^-3)/$BJ$5+L26 -> -312482.79 | AF26: AP-U/RM05 | AG26: B5//ONIOM/B1 + Bond1/B1 | AH26: =Y51-(Y5+Y8)-2.3 -> 9.2199452 | AI26: =-312506-Y51-0.8 -> 21.008182 | AJ26: =AH26+AI26 -> 30.228127 | AK26: =ABS($AI$18-AI26) -> 0.87986861 | AL26: =ABS($AJ$29-AJ26) -> 0.52812726 | AN26: =Y57-(Y5+Y7)-1.9 -> 15.14969 | AO26: =-312215.05-Y57-0.1 -> 19.237855 | AP26: =AN26+AO26 -> 34.387544 | AQ26: =ABS($AO$18-AO26) -> 2.0828786 | BI26: (kb*T)/(h*v*c) | BJ26: =(BJ10*BJ13)/(BJ8*BJ12*BJ17) -> 0.23966744
A27: TS1_RC | B27: -498.02731 | C27: -498.05065 | G27: -498.15782 | I27: -10.61 | J27: -8.47 | L27: -7.73 | N27: 0.164328 | O27: 0.176247 | P27: 0.126047 | Q27: =O27-P27 -> 0.0502 | R27: =((B27+N27)*$BJ$3*$BJ$4*10^-3)/$BJ$5 -> -312413.64 | S27: =((C27+N27)*$BJ$3*$BJ$4*10^-3)/$BJ$5 -> -312428.29 | T27: =((G27+N27)*$BJ$3*$BJ$4*10^-3)/$BJ$5 -> -312495.54 | U27: =((G27+N27)*$BJ$3*$BJ$4*10^-3)/$BJ$5 -> -312495.54 | V27: =((G27+P27)*$BJ$3*$BJ$4*10^-3)/$BJ$5 -> -312519.56 | W27: =((G27+P27)*$BJ$3*$BJ$4*10^-3)/$BJ$5+I27 -> -312530.17 | X27: =((G27+P27)*$BJ$3*$BJ$4*10^-3)/$BJ$5+J27 -> -312528.03 | Y27: =((G27+P27)*$BJ$3*$BJ$4*10^-3)/$BJ$5+K27 -> -312519.56 | AB27: =((G27+P27)*$BJ$3*$BJ$4*10^-3)/$BJ$5+L27 -> -312527.29 | AF27: AP-U/RM05 | AG27: B4//ONIOM/B1 + Bondi/B1 | AH27: =Z51-(Z5+Z8)-2.3 -> 8.9327875 | AI27: =-312496.19-Z51-0.8 -> 20.508753 | AJ27: =AH27+AI27 -> 29.441541 | AK27: =ABS($AI$18-AI27) -> 0.38043954 | AL27: =ABS($AJ$29-AJ27) -> 0.25845947 | AN27: =Z57-(Z5+Z7)-1.9 -> 14.696364 | AO27: =-312205.87-Z57-0.1 -> 18.837536 | AP27: =AN27+AO27 -> 33.533899 | AQ27: =ABS($AO$18-AO27) -> 2.4831977 | AX27: =X39 -> -414330.34 | BI27: RTln(k(T)) [kCal/mol] | BJ27: =(BJ15*BJ10*LN(BJ25)/1000)/BJ5 -> 0.75874839
A28: BS_U_TS1(-) | B28: -497.41632 | C28: -497.43782 | D28: 0.1685 | E28: -497.52801 | F28: 0.1538 | G28: -497.54289 | H28: 0.1482 | J28: -61.91 | K28: -62.96 | M28: 720.41 | N28: 0.143397 | O28: 0.155206 | P28: 0.104862 | Q28: =O28-P28 -> 0.050344 | R28: =((B28+N28)*$BJ$3*$BJ$4*10^-3)/$BJ$5 -> -312043.38 | S28: =((C28+N28)*$BJ$3*$BJ$4*10^-3)/$BJ$5 -> -312056.86 | T28: =((G28+N28)*$BJ$3*$BJ$4*10^-3)/$BJ$5 -> -312122.8 | U28: =((G28+N28)*$BJ$3*$BJ$4*10^-3)/$BJ$5 -> -312122.8 | V28: =((G28+P28)*$BJ$3*$BJ$4*10^-3)/$BJ$5 -> -312146.98 | W28: =((G28+P28)*$BJ$3*$BJ$4*10^-3)/$BJ$5+I28 -> -312146.98 | X28: =((G28+P28)*$BJ$3*$BJ$4*10^-3)/$BJ$5+J28 -> -312208.89 | Y28: =((G28+P28)*$BJ$3*$BJ$4*10^-3)/$BJ$5+K28 -> -312209.94 | AB28: =((G28+P28)*$BJ$3*$BJ$4*10^-3)/$BJ$5+L28 -> -312146.98 | AF28: AP-U/RM05 | AG28: B3//ONIOM/B1 + Bondi/B1 | AH28: =AA51-(AA5+AA8)-2.3 -> 8.5947288 | AI28: =-312439.23-AA51-0.8 -> 20.36652 | AJ28: =AH28+AI28 -> 28.961249 | AK28: =ABS($AI$18-AI28) -> 0.2382068 | AL28: =ABS($AJ$29-AJ28) -> 0.73875091 | AP28: =AN28+AO28 -> 0 | AQ28: =ABS($AO$18-AO28) -> 21.320733 | BI28: (s) | BJ28: 2
A29: BS_U_TS1(-)_(T) | C29: -497.39233 | E29: -497.48224 | G29: -497.49723 | J29: -64.95 | K29: -65.81 | N29: 0.143397 | O29: 0.155206 | P29: 0.104862 | Q29: =O29-P29 -> 0.050344 | R29: =((B29+N29)*$BJ$3*$BJ$4*10^-3)/$BJ$5 -> 89.982949 | S29: =((C29+N29)*$BJ$3*$BJ$4*10^-3)/$BJ$5 -> -312028.32 | T29: =((G29+N29)*$BJ$3*$BJ$4*10^-3)/$BJ$5 -> -312094.15 | U29: =((G29+N29)*$BJ$3*$BJ$4*10^-3)/$BJ$5 -> -312094.15 | V29: =((G29+P29)*$BJ$3*$BJ$4*10^-3)/$BJ$5 -> -312118.33 | W29: =((G29+P29)*$BJ$3*$BJ$4*10^-3)/$BJ$5+I29 -> -312118.33 | X29: =((G29+P29)*$BJ$3*$BJ$4*10^-3)/$BJ$5+J29 -> -312183.28 | Y29: =((G29+P29)*$BJ$3*$BJ$4*10^-3)/$BJ$5+K29 -> -312184.14 | AB29: =((G29+P29)*$BJ$3*$BJ$4*10^-3)/$BJ$5+L29 -> -312118.33 | AF29: exp | AJ29: 29.7 | AL29: =ABS($AJ$29-AJ29) -> 0 | BI29: RTln(s) kCal/mol | BJ29: =($BJ$10*$BJ$15*LN(BJ28)*10^-3)/BJ5 -> 0.96419861
A30: TS1(-1)_RC | B30: -497.47013 | C30: -497.49097 | E30: -497.58132 | G30: -497.59686 | J30: -55.39 | K30: -57.24 | N30: 0.149286 | O30: 0.160623 | P30: 0.110884 | Q30: =O30-P30 -> 0.049739 | R30: =((B30+N30)*$BJ$3*$BJ$4*10^-3)/$BJ$5 -> -312073.45 | S30: =((C30+N30)*$BJ$3*$BJ$4*10^-3)/$BJ$5 -> -312086.53 | T30: =((G30+N30)*$BJ$3*$BJ$4*10^-3)/$BJ$5 -> -312152.97 | U30: =((G30+N30)*$BJ$3*$BJ$4*10^-3)/$BJ$5 -> -312152.97 | V30: =((G30+P30)*$BJ$3*$BJ$4*10^-3)/$BJ$5 -> -312177.07 | W30: =((G30+P30)*$BJ$3*$BJ$4*10^-3)/$BJ$5+I30 -> -312177.07 | X30: =((G30+P30)*$BJ$3*$BJ$4*10^-3)/$BJ$5+J30 -> -312232.46 | Y30: =((G30+P30)*$BJ$3*$BJ$4*10^-3)/$BJ$5+K30 -> -312234.31 | AB30: =((G30+P30)*$BJ$3*$BJ$4*10^-3)/$BJ$5+L30 -> -312177.07
A31: OOH2_TS_RC | B31: -497.97003 | C31: -497.9943 | E31: -498.08541 | G31: -498.10116 | J31: -13.7 | K31: -11.83 | N31: 0.164436 | O31: 0.175654 | P31: 0.127428 | Q31: =O31-P31 -> 0.048226 | R31: =((B31+N31)*$BJ$3*$BJ$4*10^-3)/$BJ$5 -> -312377.63 | S31: =((C31+N31)*$BJ$3*$BJ$4*10^-3)/$BJ$5 -> -312392.86 | T31: =((G31+N31)*$BJ$3*$BJ$4*10^-3)/$BJ$5 -> -312459.92 | U31: =((G31+N31)*$BJ$3*$BJ$4*10^-3)/$BJ$5 -> -312459.92 | V31: =((G31+P31)*$BJ$3*$BJ$4*10^-3)/$BJ$5 -> -312483.14 | W31: =((G31+P31)*$BJ$3*$BJ$4*10^-3)/$BJ$5+I31 -> -312483.14 | X31: =((G31+P31)*$BJ$3*$BJ$4*10^-3)/$BJ$5+J31 -> -312496.84 | Y31: =((G31+P31)*$BJ$3*$BJ$4*10^-3)/$BJ$5+K31 -> -312494.97 | AB31: =((G31+P31)*$BJ$3*$BJ$4*10^-3)/$BJ$5+L31 -> -312483.14
A32: BS_U_OOH2_TS | B32: -497.9086 | C32: -497.96601 | D32: 0.7605 | E32: -498.05737 | F32: 0.7652 | G32: -498.07268 | H32: 0.7639 | J32: -14.46 | K32: -13.38 | M32: 52.45 | N32: 0.158979 | O32: 0.17168 | P32: 0.118584 | Q32: =O32-P32 -> 0.053096 | R32: =((B32+N32)*$BJ$3*$BJ$4*10^-3)/$BJ$5 -> -312342.51 | S32: =((C32+N32)*$BJ$3*$BJ$4*10^-3)/$BJ$5 -> -312378.53 | T32: =((G32+N32)*$BJ$3*$BJ$4*10^-3)/$BJ$5 -> -312445.47 | U32: =((G32+N32)*$BJ$3*$BJ$4*10^-3)/$BJ$5 -> -312445.47 | V32: =((G32+P32)*$BJ$3*$BJ$4*10^-3)/$BJ$5 -> -312470.82 | W32: =((G32+P32)*$BJ$3*$BJ$4*10^-3)/$BJ$5+I32 -> -312470.82 | X32: =((G32+P32)*$BJ$3*$BJ$4*10^-3)/$BJ$5+J32 -> -312485.28 | Y32: =((G32+P32)*$BJ$3*$BJ$4*10^-3)/$BJ$5+K32 -> -312484.2 | AB32: =((G32+P32)*$BJ$3*$BJ$4*10^-3)/$BJ$5+L32 -> -312470.82
A33: U_OOH2_TS_T | C33: -497.98397 | E33: -498.07536 | G33: -498.09053 | J33: -12.28 | K33: -11.28 | N33: 0.158979 | O33: 0.17168 | P33: 0.118584 | Q33: =O33-P33 -> 0.053096 | R33: =((C33+N33)*$BJ$3*$BJ$4*10^-3)/$BJ$5 -> -312389.81 | S33: =((#REF!+N33)*$BJ$3*$BJ$4*10^-3)/$BJ$5 -> #REF! | T33: =((G33+N33)*$BJ$3*$BJ$4*10^-3)/$BJ$5 -> -312456.67 | U33: =((G33+N33)*$BJ$3*$BJ$4*10^-3)/$BJ$5 -> -312456.67 | V33: =((G33+P33)*$BJ$3*$BJ$4*10^-3)/$BJ$5 -> -312482.02 | W33: =((G33+P33)*$BJ$3*$BJ$4*10^-3)/$BJ$5+I33 -> -312482.02 | X33: =((G33+P33)*$BJ$3*$BJ$4*10^-3)/$BJ$5+J33 -> -312494.3 | Y33: =((G33+P33)*$BJ$3*$BJ$4*10^-3)/$BJ$5+K33 -> -312493.3 | AB33: =((G33+P33)*$BJ$3*$BJ$4*10^-3)/$BJ$5+L33 -> -312482.02
